Workbook

Sheet LUNES
C1: FECHA | F1: 46237 | K1: TURNO | M1: DIURNO & NOCTURNO | AK1: MINI BAR | AP1: MINI BAR
B2: RESPONSABLE | F2: SARA | M2: $ TASA | P2: 890 | AK2: DESCRIPCIÓN | AL2: PRECIO | AM2: CANT # 1 | AN2: TOTAL VENTA | AP2: DESCRIPCIÓN | AQ2: PRECIO | AR2: CANT # 1 | AS2: TOTAL VENTA
AK3: AGUA PEQUEÑA | AL3: 1 | AN3: =AM3*AL3 -> 0 | AP3: SUPER POPY | AQ3: 2 | AS3: =AR3*AQ3 -> 0
B4: SENCILLA | AK4: AGUA MEDIANA | AL4: 2 | AN4: =AM4*AL4 -> 0 | AP4: GALAK | AQ4: 2.5 | AS4: =AR4*AQ4 -> 0
A5: TIPO DE HABITACION | B5: M | C5: M | D5: M | E5: M | F5: M | G5: M | H5: M | I5: M | J5: M | K5: M | L5: M | M5: M | AK5: MINI REFRESCO | AL5: 1.5 | AM5: 1 | AN5: =AM5*AL5 -> 1.5 | AP5: OREO | AQ5: 1 | AS5: =AR5*AQ5 -> 0
B6: 1 | C6: 2 | D6: 3 | E6: 4 | F6: 5 | G6: 6 | H6: 7 | I6: 8 | J6: 9 | K6: 10 | L6: 11 | M6: 12 | AD6: TTAL HB | AE6: HRAS EXTRAS | AI6: TTAL H EXT | AK6: REFRESCO 1 LTS | AL6: 2 | AM6: 1 | AN6: =AM6*AL6 -> 2 | AP6: GALLETA CLUB | AQ6: 1 | AS6: =AR6*AQ6 -> 0
A7: MATRINONIAL | B7: 1 | C7: 1 | D7: 1 | E7: 1 | F7: 1 | G7: 1 | I7: 1 | K7: 1 | L7: 1 | M7: 1 | AD7: =+C18+D18+F18+J18+L18+M18 -> 12 | AI7: =SUM(AE7:AH7) -> 0 | AK7: POWER 400ML | AL7: 1 | AN7: =AM7*AL7 -> 0 | AP7: BOM BOM BUM | AQ7: 0.3 | AS7: =AR7*AQ7 -> 0
A8: MINI SUIT | C8: 1 | D8: 1 | E8: 1 | F8: 1 | G8: 1 | I8: 1 | M8: 1 | AD8: =+B18+E18+G18+H18+I18+K18 -> 9 | AI8: =SUM(AE8:AH8) -> 0 | AK8: ROCKSTAR | AL8: 2 | AN8: =AM8*AL8 -> 0 | AP8: JABON DE BAÑO | AQ8: 2 | AR8: 1 | AS8: =AR8*AQ8 -> 2
D9: 1 | I9: 1 | M9: 1 | AI9: =SUM(AE9:AH9) -> 0 | AK9: REDBULL | AL9: 4.5 | AN9: =AM9*AL9 -> 0 | AP9: PRESERVATIVO | AQ9: 1 | AR9: 2 | AS9: =AR9*AQ9 -> 2
D10: 1 | AI10: =SUM(AE10:AH10) -> 0 | AK10: TE CRISTAL | AL10: 1.5 | AN10: =AM10*AL10 -> 0 | AP10: TE LIPTON | AQ10: 2 | AS10: =AR10*AQ10 -> 0
AD11: =SUM(AD7:AD10) -> 21 | AK11: GATORADE | AL11: 3 | AN11: =AM11*AL11 -> 0 | AP11: VITA TE | AQ11: 1.5 | AS11: =AR11*AQ11 -> 0
AK12: MALTA | AL12: 2.6 | AN12: =AM12*AL12 -> 0 | AS12: =AR12*AQ12 -> 0
AK13: SODA | AL13: 1 | AN13: =AM13*AL13 -> 0 | AS13: =AR13*AQ13 -> 0
AK14: CAROREÑA | AL14: 2 | AN14: =AM14*AL14 -> 0 | AS14: =AR14*AQ14 -> 0
AK15: CERVEZA POLAR | AL15: 2 | AN15: =AM15*AL15 -> 0 | AS15: =AR15*AQ15 -> 0
AK16: SOLERA | AL16: 1.5 | AN16: =AM16*AL16 -> 0 | AS16: =AR16*AQ16 -> 0
AK17: PACK POLAR | AL17: 6 | AN17: =AM17*AL17 -> 0 | AS17: =AR17*AQ17 -> 0
B18: =SUM(B7:B15) -> 1 | C18: =SUM(C7:C15) -> 2 | D18: =SUM(D7:D15) -> 4 | E18: =SUM(E7:E15) -> 2 | F18: =SUM(F7:F15) -> 2 | G18: =SUM(G7:G15) -> 2 | H18: =SUM(H7:H15) -> 0 | I18: =SUM(I7:I15) -> 3 | ... AC18: =SUM(AC7:AC15) -> 0 | AK18: DORITO PEQ | AL18: 2 | AN18: =AM18*AL18 -> 0 | AS18: =AR18*AQ18 -> 0
AK19: DORITO MED | AL19: 4 | AN19: =AM19*AL19 -> 0 | AS19: =AR19*AQ19 -> 0
B20: PERNOCTA | AK20: CHEESE TREE PEQ | AL20: 2 | AN20: =AM20*AL20 -> 0 | AS20: =AR20*AQ20 -> 0
A21: TIPO DE HABITACION | B21: M | C21: M | D21: M | E21: M | F21: M | G21: M | H21: M | I21: M | J21: M | K21: M | L21: M | M21: M | AK21: CHEESE TREE MED | AL21: 3 | AN21: =AM21*AL21 -> 0 | AS21: =AR21*AQ21 -> 0
B22: 1 | C22: 2 | D22: 3 | E22: 4 | F22: 5 | G22: 6 | H22: 7 | I22: 8 | J22: 9 | K22: 10 | L22: 11 | M22: 12 | AD22: TTAL HB | AE22: HRAS EXTRAS | AI22: TTAL H EXT | AK22: PEPITO FIRTOLAY | AL22: 1 | AN22: =AM22*AL22 -> 0 | AS22: =AR22*AQ22 -> 0
A23: MATRINONIAL | C23: 1 | F23: 1 | H23: 1 | J23: 1 | L23: 1 | AD23: =+C34+D34+J34+L34+M34 -> 3 | AI23: =SUM(AE23:AH23) -> 0 | AK23: TOSTON TOM | AL23: 2 | AN23: =AM23*AL23 -> 0 | AS23: =AR23*AQ23 -> 0
A24: MINI SUIT | AD24: =+B34+E34+G34+H34+I34+K34 -> 1 | AI24: =SUM(AE24:AH24) -> 0 | AK24: COCOSSETE | AL24: 2 | AM24: 1 | AN24: =AM24*AL24 -> 2 | AS24: =AR24*AQ24 -> 0
AI25: =SUM(AE25:AH25) -> 0 | AK25: SAMBA | AL25: 2 | AN25: =AM25*AL25 -> 0 | AS25: =AR25*AQ25 -> 0
AI26: =SUM(AE26:AH26) -> 0 | AK26: FREGELL | AL26: 1 | AN26: =AM26*AL26 -> 0 | AS26: =AR26*AQ26 -> 0
AD27: =SUM(AD23:AD26) -> 4 | AN27: =SUM(AN3:AN26) -> 5.5 | AS27: =SUM(AS3:AS26) -> 4
AK29: DAÑOS, SERVICIOS Y EXTRAS
AK30: DESINFECCION | AL30: 4 | AN30: =AM30*AL30 -> 0
AK31: DAÑOS | AL31: 5 | AN31: =AM31*AL31 -> 0
AK32: SERV LAV X PIEZA | AL32: 1 | AN32: =AM32*AL32 -> 0
AK33: DECORACION MOD 1 | AL33: 5 | AN33: =AM33*AL33 -> 0
B34: =SUM(B23:B31) -> 0 | C34: =SUM(C23:C31) -> 1 | D34: =SUM(D23:D31) -> 0 | E34: =SUM(E23:E31) -> 0 | F34: =SUM(F23:F31) -> 1 | G34: =SUM(G23:G31) -> 0 | H34: =SUM(H23:H31) -> 1 | I34: =SUM(I23:I31) -> 0 | ... AC34: =SUM(AC23:AC31) -> 0 | AK34: DECORACION MOD 2 | AL34: 5 | AN34: =AM34*AL34 -> 0
AK35: DECORACION MOD 3 | AL35: 5 | AN35: =AM35*AL35 -> 0
A36: CUADRE DE CAJA | O36: SENCILLA | S36: PERNOCTA | Z36: TOTAL HABITACIÓN | AF36: =O42+S42 -> 25 | AK36: OTROS DAÑOS | AL36: 5 | AN36: =AM36*AL36 -> 0
A37: HABITACIÓN | D37: SENCILLA | F37: HORAS ADICIONAL | H37: PERNOTA | L37: HABITACIÓN | O37: CANTID. HAB | Q37: HORAS ADIC | S37: CANTID. HAB | U37: VENTA | Z37: TOTAL VENTA HOTEL | AF37: =U42 -> 312 | AN37: =SUM(AN30:AN36) -> 0
A38: MATRINONIAL | D38: 10 | F38: 2.5 | H38: 20 | L38: MATRINONIAL | O38: =AD7 -> 12 | Q38: =AI7+AI23 -> 0 | S38: =AD23 -> 3 | U38: =S38*H38+O38*D38+Q38*F38 -> 180 | Z38: ACOMPAÑATE | AF38: =AN39 -> 0
A39: MINI SUITE | D39: 12 | F39: 3 | H39: 24 | L39: MINI SUITE | O39: =AD8 -> 9 | Q39: =AI8 -> 0 | S39: =AD24 -> 1 | U39: =S39*H39+O39*D39+Q39*F39 -> 132 | Z39: DAÑOS, SERV Y OTROS | AF39: =AN37 -> 0 | AK39: ACOMPAÑANTE | AL39: 5 | AN39: =AM39*AL39 -> 0
O40: =AD9 -> 0 | Q40: =AI9 -> 0 | S40: =AD25 -> 0 | U40: =S40*H40+O40*D40+Q40*F40 -> 0 | Z40: MINI BAR | AF40: =+AN27+AS27 -> 9.5
O41: =AD10 -> 0 | Q41: =AI10 -> 0 | S41: =AD26 -> 0 | U41: =S41*H41+O41*D41+Q41*F41 -> 0 | Z41: TOTAL VENTA HOTEL | AF41: =SUM(AF37:AF40) -> 321.5
...

Sheet CIERRE LUNES
A1: *
C4: TASA INTERNA
D5: =+LUNES!P2 -> 890
B6: 45758
B7: =LUNES!F1 -> 46237
B8: TOTAL HABITACIONES | C8: =+LUNES!I98 -> 25
B9: VENTAS HABITACIONES | C9: =LUNES!AF37*D5 -> 277680 | D9: =+C9/D5 -> 312
B10: INGRESO DE ACOMPAÑANTE | C10: =LUNES!AF38*'CIERRE LUNES'!D5 -> 0 | D10: =C10/D5 -> 0
B11: VENTAS MINI BAR | C11: =LUNES!AF40*'CIERRE LUNES'!D5 -> 8455 | D11: =+C11/D5 -> 9.5
B12: DAÑOS, SERV Y OTROS | C12: =LUNES!AF39*'CIERRE LUNES'!D5 -> 0 | D12: =C12/D5 -> 0
D13: =+C13/D5 -> 0
B15: TOTAL VENTAS | C15: =SUM(C9:C14) -> 286135 | D15: =+C15/D5 -> 321.5
B17: DISPONIBLE
B18: DESCRIPCION | C18: DESGLOSE | D18: INGRESO REAL DIARIO
B19: DIVISAS | C19: =LUNES!S47 -> 138 | D19: =+C19 -> 138
B20: EFECTIVO BSS | C20: =LUNES!S45 -> 1800 | D20: =+C20/D5 -> 2.0224719
B21: TRANSF / PAGO MOVIL | C21: =LUNES!S46 -> 179315 | D21: =+C21/D5 -> 201.47753
B22: ZELLE
B23: EFECTIVO $ | C23: =+C19 -> 138 | D23: =SUM(D19:D22) -> 341.5
B24: EFECTIVO BS | C24: =+C20 -> 1800 | D24: =D23-D15 -> 20
B26: EGRESOS | C26: BS | D26: $
C32: =SUM(C27:C31) -> 0 | D32: =SUM(D27:D31) -> 0
B34: EFECTIVO VENTA DIARIA BS | C34: =+C24 -> 1800
B35: EFECTIVO VENTA DIARIA $ | C35: =+C23 -> 138
B36: EGRESOS BS | C36: =+C32 -> 0
B37: EGRESOS $ | C37: =+D32 -> 0
B38: TOTAL A ENTREGAR $ | C38: =+C35-C37 -> 138
B39: TOTAL ENTREGAR BS EFEC | C39: =+C34-C36 -> 1800
B41: OBSERVACION:

Sheet MARTES
C1: FECHA | F1: 46238 | K1: TURNO | M1: DIURNO & NOCTURNO | AK1: MINI BAR | AP1: MINI BAR
B2: RESPONSABLE | F2: HILDA | M2: $ TASA | P2: 890 | AK2: DESCRIPCIÓN | AL2: PRECIO | AM2: CANT # 1 | AN2: TOTAL VENTA | AP2: DESCRIPCIÓN | AQ2: PRECIO | AR2: CANT # 1 | AS2: TOTAL VENTA
AK3: AGUA PEQUEÑA | AL3: 1 | AN3: =AM3*AL3 -> 0 | AP3: SUPER POPY | AQ3: 2 | AS3: =AR3*AQ3 -> 0
B4: SENCILLA | AK4: AGUA MEDIANA | AL4: 2 | AM4: 2 | AN4: =AM4*AL4 -> 4 | AP4: GALAK | AQ4: 2.5 | AS4: =AR4*AQ4 -> 0
A5: TIPO DE HABITACION | B5: M | C5: M | D5: M | E5: M | F5: M | G5: M | H5: M | I5: M | J5: M | K5: M | L5: M | M5: M | AK5: MINI REFRESCO | AL5: 1.5 | AN5: =AM5*AL5 -> 0 | AP5: OREO | AQ5: 1 | AS5: =AR5*AQ5 -> 0
B6: 1 | C6: 2 | D6: 3 | E6: 4 | F6: 5 | G6: 6 | H6: 7 | I6: 8 | J6: 9 | K6: 10 | L6: 11 | M6: 12 | AD6: TTAL HB | AE6: HRAS EXTRAS | AI6: TTAL H EXT | AK6: REFRESCO 1 LTS | AL6: 2 | AN6: =AM6*AL6 -> 0 | AP6: GALLETA CLUB | AQ6: 1 | AS6: =AR6*AQ6 -> 0
A7: MATRINONIAL | D7: 1 | E7: 1 | F7: 1 | G7: 1 | H7: 1 | I7: 1 | K7: 1 | M7: 1 | AD7: =+C18+D18+F18+J18+L18+M18 -> 10 | AI7: =SUM(AE7:AH7) -> 0 | AK7: POWER 400ML | AL7: 1 | AN7: =AM7*AL7 -> 0 | AP7: BOM BOM BUM | AQ7: 0.3 | AS7: =AR7*AQ7 -> 0
A8: MINI SUIT | D8: 1 | E8: 1 | F8: 1 | G8: 1 | I8: 1 | M8: 1 | AD8: =+B18+E18+G18+H18+I18+K18 -> 10 | AI8: =SUM(AE8:AH8) -> 0 | AK8: ROCKSTAR | AL8: 2 | AN8: =AM8*AL8 -> 0 | AP8: JABON DE BAÑO | AQ8: 2 | AS8: =AR8*AQ8 -> 0
D9: 1 | E9: 1 | F9: 1 | AI9: =SUM(AE9:AH9) -> 0 | AK9: REDBULL | AL9: 4.5 | AM9: 1 | AN9: =AM9*AL9 -> 4.5 | AP9: PRESERVATIVO | AQ9: 1 | AS9: =AR9*AQ9 -> 0
E10: 1 | F10: 1 | AI10: =SUM(AE10:AH10) -> 0 | AK10: TE CRISTAL | AL10: 1.5 | AN10: =AM10*AL10 -> 0 | AP10: TE LIPTON | AQ10: 2 | AS10: =AR10*AQ10 -> 0
F11: 1 | AD11: =SUM(AD7:AD10) -> 20 | AK11: GATORADE | AL11: 3 | AN11: =AM11*AL11 -> 0 | AP11: VITA TE | AQ11: 1.5 | AS11: =AR11*AQ11 -> 0
AK12: MALTA | AL12: 2 | AM12: 2 | AN12: =AM12*AL12 -> 4 | AS12: =AR12*AQ12 -> 0
AK13: SODA | AL13: 1 | AN13: =AM13*AL13 -> 0 | AS13: =AR13*AQ13 -> 0
AK14: CAROREÑA | AL14: 2 | AN14: =AM14*AL14 -> 0 | AS14: =AR14*AQ14 -> 0
AK15: CERVEZA POLAR | AL15: 2 | AN15: =AM15*AL15 -> 0 | AS15: =AR15*AQ15 -> 0
AK16: SOLERA | AL16: 1.5 | AN16: =AM16*AL16 -> 0 | AS16: =AR16*AQ16 -> 0
AK17: PACK POLAR | AL17: 6 | AN17: =AM17*AL17 -> 0 | AS17: =AR17*AQ17 -> 0
B18: =SUM(B7:B15) -> 0 | C18: =SUM(C7:C15) -> 0 | D18: =SUM(D7:D15) -> 3 | E18: =SUM(E7:E15) -> 4 | F18: =SUM(F7:F15) -> 5 | G18: =SUM(G7:G15) -> 2 | H18: =SUM(H7:H15) -> 1 | I18: =SUM(I7:I15) -> 2 | ... AC18: =SUM(AC7:AC15) -> 0 | AK18: DORITO PEQ | AL18: 2 | AM18: 1 | AN18: =AM18*AL18 -> 2 | AS18: =AR18*AQ18 -> 0
AK19: DORITO MED | AL19: 4 | AN19: =AM19*AL19 -> 0 | AS19: =AR19*AQ19 -> 0
B20: PERNOCTA | AK20: CHEESE TREE PEQ | AL20: 2 | AN20: =AM20*AL20 -> 0 | AS20: =AR20*AQ20 -> 0
A21: TIPO DE HABITACION | B21: M | C21: M | D21: M | E21: M | F21: M | G21: M | H21: M | I21: M | J21: M | K21: M | L21: M | M21: M | AK21: CHEESE TREE MED | AL21: 3 | AN21: =AM21*AL21 -> 0 | AS21: =AR21*AQ21 -> 0
B22: 1 | C22: 2 | D22: 3 | E22: 4 | F22: 5 | G22: 6 | H22: 7 | I22: 8 | J22: 9 | K22: 10 | L22: 11 | M22: 12 | AD22: TTAL HB | AE22: HRAS EXTRAS | AI22: TTAL H EXT | AK22: PEPITO FIRTOLAY | AL22: 1 | AM22: 1 | AN22: =AM22*AL22 -> 1 | AS22: =AR22*AQ22 -> 0
A23: MATRINONIAL | B23: 1 | C23: 1 | J23: 1 | L23: 1 | M23: 1 | AD23: =+C34+D34+F34+J34+L34+M34 -> 4 | AI23: =SUM(AE23:AH23) -> 0 | AK23: TOSTON TOM | AL23: 2 | AM23: 1 | AN23: =AM23*AL23 -> 2 | AS23: =AR23*AQ23 -> 0
A24: MINI SUIT | AD24: =+B34+E34+G34+H34+I34+K34 -> 1 | AI24: =SUM(AE24:AH24) -> 0 | AK24: COCOSSETE | AL24: 2 | AN24: =AM24*AL24 -> 0 | AS24: =AR24*AQ24 -> 0
AI25: =SUM(AE25:AH25) -> 0 | AK25: SAMBA | AL25: 2 | AN25: =AM25*AL25 -> 0 | AS25: =AR25*AQ25 -> 0
AD26: =R34+S34 -> 0 | AI26: =SUM(AE26:AH26) -> 0 | AK26: FREGELL | AL26: 1 | AN26: =AM26*AL26 -> 0 | AS26: =AR26*AQ26 -> 0
AD27: =SUM(AD23:AD26) -> 5 | AN27: =SUM(AN3:AN26) -> 17.5 | AS27: =SUM(AS3:AS26) -> 0
AK29: DAÑOS, SERVICIOS Y EXTRAS
AK30: DESINFECCION | AL30: 4 | AN30: =AM30*AL30 -> 0
AK31: DAÑOS | AL31: 5 | AN31: =AM31*AL31 -> 0
AK32: SERV LAV X PIEZA | AL32: 1 | AN32: =AM32*AL32 -> 0
AK33: DECORACION MOD 1 | AL33: 5 | AN33: =AM33*AL33 -> 0
B34: =SUM(B23:B31) -> 1 | C34: =SUM(C23:C31) -> 1 | D34: =SUM(D23:D31) -> 0 | E34: =SUM(E23:E31) -> 0 | F34: =SUM(F23:F31) -> 0 | G34: =SUM(G23:G31) -> 0 | H34: =SUM(H23:H31) -> 0 | I34: =SUM(I23:I31) -> 0 | ... AC34: =SUM(AC23:AC31) -> 0 | AK34: DECORACION MOD 2 | AL34: 5 | AN34: =AM34*AL34 -> 0
AK35: DECORACION MOD 3 | AL35: 5 | AN35: =AM35*AL35 -> 0
A36: CUADRE DE CAJA | O36: SENCILLA | S36: PERNOCTA | Z36: TOTAL HABITACIÓN | AF36: =O42+S42 -> 25 | AK36: OTROS DAÑOS | AL36: 5 | AN36: =AM36*AL36 -> 0
A37: HABITACIÓN | D37: SENCILLA | F37: HORAS ADICIONAL | H37: PERNOTA | L37: HABITACIÓN | O37: CANTID. HAB | Q37: HORAS ADIC | S37: CANTID. HAB | U37: VENTA | Z37: TOTAL VENTA HOTEL | AF37: =U42 -> 324 | AN37: =SUM(AN30:AN36) -> 0
A38: MATRINONIAL | D38: 10 | F38: 2.5 | H38: 20 | L38: MATRINONIAL | O38: =AD7 -> 10 | Q38: =AI7+AI23 -> 0 | S38: =AD23 -> 4 | U38: =S38*H38+O38*D38+Q38*F38 -> 180 | Z38: ACOMPAÑATE | AF38: =AN39 -> 0
A39: MINI SUITE | D39: 12 | F39: 3 | H39: 24 | L39: MINI SUITE | O39: =AD8 -> 10 | Q39: =AI8 -> 0 | S39: =AD24 -> 1 | U39: =S39*H39+O39*D39+Q39*F39 -> 144 | Z39: DAÑOS, SERV Y OTROS | AF39: =AN37 -> 0 | AK39: ACOMPAÑANTE | AL39: 5 | AN39: =AM39*AL39 -> 0
O40: =AD9 -> 0 | Q40: =AI9 -> 0 | S40: =AD25 -> 0 | U40: =S40*H40+O40*D40+Q40*F40 -> 0 | Z40: MINI BAR | AF40: =+AN27+AS27 -> 17.5
O41: =AD10 -> 0 | Q41: =AI10 -> 0 | S41: =AD26 -> 0 | U41: =S41*H41+O41*D41+Q41*F41 -> 0 | Z41: TOTAL VENTA HOTEL | AF41: =SUM(AF37:AF40) -> 341.5
...

Sheet CIERRE MARTES
A1: *
C4: TASA INTERNA
D5: =+MARTES!P2 -> 890
B6: 45758
B7: =MARTES!F1 -> 46238
B8: TOTAL HABITACIONES | C8: =MARTES!AF36 -> 25
B9: VENTAS HABITACIONES | C9: =MARTES!AF37*'CIERRE MARTES'!D5 -> 288360 | D9: =C9/D5 -> 324
B10: INGRESO DE ACOMPAÑANTE | C10: =MARTES!AF38*'CIERRE MARTES'!D5 -> 0 | D10: =C10/D5 -> 0
B11: VENTAS MINI BAR | C11: =MARTES!AF40*'CIERRE MARTES'!D5 -> 15575 | D11: =C11/D5 -> 17.5
B12: DAÑOS, SERV Y OTROS | C12: =MARTES!AF39*'CIERRE MARTES'!D5 -> 0 | D12: =C12/D5 -> 0
B15: TOTAL VENTAS | C15: =SUM(C9:C14) -> 303935 | D15: =+C15/D5 -> 341.5
B17: DISPONIBLE
B18: DESCRIPCION | C18: DESGLOSE | D18: INGRESO REAL DIARIO
B19: DIVISAS | C19: =MARTES!K51 -> 165 | D19: =+C19 -> 165
B20: EFECTIVO BSS | C20: =MARTES!S45 -> 4040 | D20: =+C20/D5 -> 4.5393258
B21: TRANSF / PAGO MOVIL | C21: =MARTES!S46 -> 153920 | D21: =+C21/D5 -> 172.94382
B22: ZELLE
B23: EFECTIVO $ | C23: =+C19 -> 165 | D23: =SUM(D19:D22) -> 342.48315
B24: EFECTIVO BS | C24: =+C20 -> 4040 | D24: =D23-D15 -> 0.98314607
B26: EGRESOS | C26: BS | D26: $
C32: =SUM(C27:C31) -> 0 | D32: =SUM(D27:D31) -> 0
B34: EFECTIVO VENTA DIARIA BS | C34: =+C24 -> 4040
B35: EFECTIVO VENTA DIARIA $ | C35: =+C23 -> 165
B36: EGRESOS BS | C36: =+C32 -> 0
B37: EGRESOS $ | C37: =+D32 -> 0
B38: TOTAL A ENTREGAR $ | C38: =+C35-C37 -> 165
B39: TOTAL ENTREGAR BS EFEC | C39: =+C34-C36 -> 4040
B41: OBSERVACION:

Sheet MIERCOLES
C1: FECHA | F1: DAI | K1: TURNO | M1: DIURNO & NOCTURNO | AK1: MINI BAR | AP1: MINI BAR
C2: RESPONSABLE | F2: 46239 | M2: $ TASA | P2: 890 | AK2: DESCRIPCIÓN | AL2: PRECIO | AM2: CANT # 1 | AN2: TOTAL VENTA | AP2: DESCRIPCIÓN | AQ2: PRECIO | AR2: CANT # 1 | AS2: TOTAL VENTA
AK3: AGUA PEQUEÑA | AL3: 1 | AN3: =AM3*AL3 -> 0 | AP3: SUPER POPY | AQ3: 2 | AS3: =AR3*AQ3 -> 0
B4: SENCILLA | AK4: AGUA MEDIANA | AL4: 2 | AM4: 3 | AN4: =AM4*AL4 -> 6 | AP4: GALAK | AQ4: 2.5 | AS4: =AR4*AQ4 -> 0
A5: TIPO DE HABITACION | B5: M | C5: M | D5: M | E5: M | F5: M | G5: M | H5: M | I5: M | J5: M | K5: M | L5: M | M5: M | AK5: MINI REFRESCO | AL5: 1.5 | AN5: =AM5*AL5 -> 0 | AP5: OREO | AQ5: 1 | AS5: =AR5*AQ5 -> 0
B6: 1 | C6: 2 | D6: 3 | E6: 4 | F6: 5 | G6: 6 | H6: 7 | I6: 8 | J6: 9 | K6: 10 | L6: 11 | M6: 12 | AD6: TTAL HB | AE6: HRAS EXTRAS | AI6: TTAL H EXT | AK6: REFRESCO 1 LTS | AL6: 2 | AM6: 1 | AN6: =AM6*AL6 -> 2 | AP6: GALLETA CLUB | AQ6: 1 | AS6: =AR6*AQ6 -> 0
A7: MATRINONIAL | C7: 1 | D7: 1 | E7: 1 | F7: 1 | G7: 1 | H7: 1 | J7: 1 | L7: 1 | M7: 1 | AD7: =+C18+D18+F18+J18+L18+M18 -> 15 | AI7: =SUM(AE7:AH7) -> 0 | AK7: POWER 400ML | AL7: 1 | AN7: =AM7*AL7 -> 0 | AP7: BOM BOM BUM | AQ7: 0.3 | AS7: =AR7*AQ7 -> 0
A8: MINI SUITE | C8: 1 | D8: 1 | E8: 1 | F8: 1 | J8: 1 | L8: 1 | AD8: =+B18+E18+G18+H18+I18+K18 -> 4 | AI8: =SUM(AE8:AH8) -> 0 | AK8: ROCKSTAR | AL8: 2 | AN8: =AM8*AL8 -> 0 | AP8: JABON DE BAÑO | AQ8: 2 | AS8: =AR8*AQ8 -> 0
C9: 1 | D9: 1 | J9: 1 | AI9: =SUM(AE9:AH9) -> 0 | AK9: REDBULL | AL9: 4.5 | AN9: =AM9*AL9 -> 0 | AP9: PRESERVATIVO | AQ9: 1 | AR9: 1 | AS9: =AR9*AQ9 -> 1
C10: 1 | AI10: =SUM(AE10:AH10) -> 0 | AK10: TE CRISTAL | AL10: 1.5 | AN10: =AM10*AL10 -> 0 | AP10: TE LIPTON | AQ10: 2 | AS10: =AR10*AQ10 -> 0
AD11: =SUM(AD7:AD10) -> 19 | AK11: GATORADE | AL11: 3 | AM11: 2 | AN11: =AM11*AL11 -> 6 | AP11: VITA TE | AQ11: 1.5 | AS11: =AR11*AQ11 -> 0
AK12: MALTA | AL12: 2.6 | AN12: =AM12*AL12 -> 0 | AS12: =AR12*AQ12 -> 0
AK13: SODA | AL13: 1 | AN13: =AM13*AL13 -> 0 | AS13: =AR13*AQ13 -> 0
AK14: CAROREÑA | AL14: 2 | AN14: =AM14*AL14 -> 0 | AS14: =AR14*AQ14 -> 0
AK15: CERVEZA POLAR | AL15: 2 | AN15: =AM15*AL15 -> 0 | AS15: =AR15*AQ15 -> 0
AK16: SOLERA | AL16: 1.5 | AN16: =AM16*AL16 -> 0 | AS16: =AR16*AQ16 -> 0
AK17: PACK POLAR | AL17: 6 | AN17: =AM17*AL17 -> 0 | AS17: =AR17*AQ17 -> 0
B18: =SUM(B7:B15) -> 0 | C18: =SUM(C7:C15) -> 4 | D18: =SUM(D7:D15) -> 3 | E18: =SUM(E7:E15) -> 2 | F18: =SUM(F7:F15) -> 2 | G18: =SUM(G7:G15) -> 1 | H18: =SUM(H7:H15) -> 1 | I18: =SUM(I7:I15) -> 0 | ... AC18: =SUM(AC7:AC15) -> 0 | AK18: DORITO PEQ | AL18: 2 | AN18: =AM18*AL18 -> 0 | AS18: =AR18*AQ18 -> 0
AK19: DORITO MED | AL19: 4 | AN19: =AM19*AL19 -> 0 | AS19: =AR19*AQ19 -> 0
B20: PERNOCTA | AK20: CHEESE TREE PEQ | AL20: 2 | AN20: =AM20*AL20 -> 0 | AS20: =AR20*AQ20 -> 0
A21: TIPO DE HABITACION | B21: M | C21: M | D21: M | E21: M | F21: M | G21: M | H21: M | I21: M | J21: M | K21: M | L21: M | M21: M | AK21: CHEESE TREE MED | AL21: 3 | AN21: =AM21*AL21 -> 0 | AS21: =AR21*AQ21 -> 0
B22: 1 | C22: 2 | D22: 3 | E22: 4 | F22: 5 | G22: 6 | H22: 7 | I22: 8 | J22: 9 | K22: 10 | L22: 11 | M22: 12 | AD22: TTAL HB | AE22: HRAS EXTRAS | AI22: TTAL H EXT | AK22: PEPITO FIRTOLAY | AL22: 1 | AN22: =AM22*AL22 -> 0 | AS22: =AR22*AQ22 -> 0
A23: MATRINONIAL | G23: 1 | M23: 1 | AD23: =+C34+D34+F34+J34+L34+M34 -> 1 | AI23: =SUM(AE23:AH23) -> 0 | AK23: TOSTON TOM | AL23: 2 | AN23: =AM23*AL23 -> 0 | AS23: =AR23*AQ23 -> 0
A24: MINI SUITE | AD24: =+B34+E34+G34+H34+I34+K34 -> 1 | AI24: =SUM(AE24:AH24) -> 0 | AK24: COCOSSETE | AL24: 2 | AN24: =AM24*AL24 -> 0 | AS24: =AR24*AQ24 -> 0
AI25: =SUM(AE25:AH25) -> 0 | AK25: SAMBA | AL25: 2 | AN25: =AM25*AL25 -> 0 | AS25: =AR25*AQ25 -> 0
AD26: =R34+S34 -> 0 | AI26: =SUM(AE26:AH26) -> 0 | AK26: FREGELL | AL26: 1 | AN26: =AM26*AL26 -> 0 | AS26: =AR26*AQ26 -> 0
AD27: =SUM(AD23:AD26) -> 2 | AN27: =SUM(AN3:AN26) -> 14 | AS27: =SUM(AS3:AS26) -> 1
AK29: DAÑOS, SERVICIOS Y EXTRAS
AK30: DESINFECCION | AL30: 4 | AN30: =AM30*AL30 -> 0
AK31: DAÑOS | AL31: 5 | AN31: =AM31*AL31 -> 0
AK32: SERV LAV X PIEZA | AL32: 1 | AN32: =AM32*AL32 -> 0
AK33: DECORACION MOD 1 | AL33: 5 | AN33: =AM33*AL33 -> 0
B34: =SUM(B23:B31) -> 0 | C34: =SUM(C23:C31) -> 0 | D34: =SUM(D23:D31) -> 0 | E34: =SUM(E23:E31) -> 0 | F34: =SUM(F23:F31) -> 0 | G34: =SUM(G23:G31) -> 1 | H34: =SUM(H23:H31) -> 0 | I34: =SUM(I23:I31) -> 0 | ... AC34: =SUM(AC23:AC31) -> 0 | AK34: DECORACION MOD 2 | AL34: 5 | AN34: =AM34*AL34 -> 0
AK35: DECORACION MOD 3 | AL35: 5 | AN35: =AM35*AL35 -> 0
A36: CUADRE DE CAJA | O36: SENCILLA | S36: PERNOCTA | Z36: TOTAL HABITACIÓN | AF36: =O42+S42 -> 21 | AK36: OTROS DAÑOS | AL36: 5 | AN36: =AM36*AL36 -> 0
A37: HABITACIÓN | D37: SENCILLA | F37: HORAS ADICIONAL | H37: PERNOTA | L37: HABITACIÓN | O37: CANTID. HAB | Q37: HORAS ADIC | S37: CANTID. HAB | U37: VENTA | Z37: TOTAL VENTA HOTEL | AF37: =U42 -> 242 | AN37: =SUM(AN30:AN36) -> 0
A38: MATRINONIAL | D38: 10 | F38: 2.5 | H38: 20 | L38: MATRINONIAL | O38: =AD7 -> 15 | Q38: =AI7+AI23 -> 0 | S38: =AD23 -> 1 | U38: =S38*H38+O38*D38+Q38*F38 -> 170 | Z38: ACOMPAÑATE | AF38: =AN39 -> 0
A39: MINI SUITE | D39: 12 | F39: 3 | H39: 24 | L39: MINI SUITE | O39: =AD8 -> 4 | Q39: =AI8 -> 0 | S39: =AD24 -> 1 | U39: =S39*H39+O39*D39+Q39*F39 -> 72 | Z39: DAÑOS, SERV Y OTROS | AF39: =AN37 -> 0 | AK39: ACOMPAÑANTE | AL39: 5 | AN39: =AM39*AL39 -> 0
O40: =AD9 -> 0 | Q40: =AI9 -> 0 | S40: =AD25 -> 0 | U40: =S40*H40+O40*D40+Q40*F40 -> 0 | Z40: MINI BAR | AF40: =+AN27+AS27 -> 15
O41: =AD10 -> 0 | Q41: =AI10 -> 0 | S41: =AD26 -> 0 | U41: =S41*H41+O41*D41+Q41*F41 -> 0 | Z41: TOTAL VENTA HOTEL | AF41: =SUM(AF37:AF40) -> 257
...

Sheet CIERRE MIERCOLES
A1: *
C4: TASA INTERNA
D5: =+MIERCOLES!P2 -> 890
B6: 45758
B7: =MIERCOLES!F1 -> DAI
B8: TOTAL HABITACIONES | C8: =MIERCOLES!AF36 -> 21
B9: VENTAS HABITACIONES | C9: =MIERCOLES!AF37*MIERCOLES!P2 -> 215380 | D9: =+C9/D5 -> 242
B10: INGRESO DE ACOMPAÑANTE | C10: =+MIERCOLES!AF38*'CIERRE MIERCOLES'!D5 -> 0 | D10: =C10/D5 -> 0
B11: VENTAS MINI BAR | C11: =MIERCOLES!AN27*MIERCOLES!P2 -> 12460 | D11: =+C11/D5 -> 14
B12: DAÑOS, SERV Y OTROS | C12: =MIERCOLES!AN37*MIERCOLES!P2 -> 0 | D12: =C12/D5 -> 0
D13: =+C13/D5 -> 0
B15: TOTAL VENTAS | C15: =SUM(C9:C14) -> 227840 | D15: =+C15/D5 -> 256
B17: DISPONIBLE
B18: DESCRIPCION | C18: DESGLOSE | D18: INGRESO REAL DIARIO
B19: DIVISAS | C19: =MIERCOLES!K51 -> 129 | D19: =+C19 -> 129
B20: EFECTIVO BSS | C20: =MIERCOLES!F51 -> 23140 | D20: =+C20/D5 -> 26
B21: TRANSF / PAGO MOVIL | C21: =MIERCOLES!S46 -> 90780 | D21: =+C21/D5 -> 102
B22: ZELLE
B23: EFECTIVO $ | C23: =+C19 -> 129 | D23: =SUM(D19:D22) -> 257
B24: EFECTIVO BS | C24: =+C20 -> 23140 | D24: =D23-D15 -> 1
B26: EGRESOS | C26: BS | D26: $
C32: =SUM(C27:C31) -> 0 | D32: =SUM(D27:D31) -> 0
B34: EFECTIVO VENTA DIARIA BS | C34: =+C24 -> 23140
B35: EFECTIVO VENTA DIARIA $ | C35: =+C23 -> 129
B36: EGRESOS BS | C36: =+C32 -> 0
B37: EGRESOS $ | C37: =+D32 -> 0
B38: TOTAL A ENTREGAR $ | C38: =+C35-C37 -> 129
B39: TOTAL ENTREGAR BS EFEC | C39: =+C34-C36 -> 23140

Sheet JUEVES
C1: FECHA | F1: 46241 | K1: TURNO | M1: DIURNO & NOCTURNO | AK1: MINI BAR | AP1: MINI BAR
C2: RESPONSABLE | F2: SARA | M2: $ TASA | P2: 890 | AK2: DESCRIPCIÓN | AL2: PRECIO | AM2: CANT # 1 | AN2: TOTAL VENTA | AP2: DESCRIPCIÓN | AQ2: PRECIO | AR2: CANT # 1 | AS2: TOTAL VENTA
AK3: AGUA PEQUEÑA | AL3: 1 | AN3: =AM3*AL3 -> 0 | AP3: SUPER POPY | AQ3: 2 | AS3: =AR3*AQ3 -> 0
B4: SENCILLA | AK4: AGUA MEDIANA | AL4: 2 | AN4: =AM4*AL4 -> 0 | AP4: GALAK | AQ4: 2.5 | AS4: =AR4*AQ4 -> 0
A5: TIPO DE HABITACION | B5: M | C5: M | D5: M | E5: M | F5: M | G5: M | H5: M | I5: M | J5: M | K5: M | L5: M | M5: M | AK5: MINI REFRESCO | AL5: 1.5 | AN5: =AM5*AL5 -> 0 | AP5: OREO | AQ5: 1 | AS5: =AR5*AQ5 -> 0
B6: 1 | C6: 2 | D6: 3 | E6: 4 | F6: 5 | G6: 6 | H6: 7 | I6: 8 | J6: 9 | K6: 10 | L6: 11 | M6: 12 | AD6: TTAL HB | AE6: HRAS EXTRAS | AI6: TTAL H EXT | AK6: REFRESCO 1 LTS | AL6: 2 | AN6: =AM6*AL6 -> 0 | AP6: GALLETA CLUB | AQ6: 1 | AS6: =AR6*AQ6 -> 0
A7: MATRINONIAL | B7: 1 | C7: 1 | D7: 1 | E7: 1 | F7: 1 | G7: 1 | H7: 1 | I7: 1 | J7: 1 | K7: 1 | L7: 1 | M7: 1 | AD7: =+C18+D18+J18+L18+M18+F18 -> 14 | AI7: =SUM(AE7:AH7) -> 0 | AK7: POWER 400ML | AL7: 1 | AN7: =AM7*AL7 -> 0 | AP7: BOM BOM BUM | AQ7: 0.3 | AS7: =AR7*AQ7 -> 0
A8: MINI SUITE | D8: 1 | F8: 1 | G8: 1 | H8: 1 | J8: 1 | L8: 1 | M8: 1 | AD8: =+B18+E18+G18+H18+I18+K18 -> 8 | AI8: =SUM(AE8:AH8) -> 0 | AK8: ROCKSTAR | AL8: 2 | AN8: =AM8*AL8 -> 0 | AP8: JABON DE BAÑO | AQ8: 2 | AS8: =AR8*AQ8 -> 0
F9: 1 | L9: 1 | M9: 1 | AI9: =SUM(AE9:AH9) -> 0 | AK9: REDBULL | AL9: 4.5 | AN9: =AM9*AL9 -> 0 | AP9: PRESERVATIVO | AQ9: 1 | AS9: =AR9*AQ9 -> 0
AI10: =SUM(AE10:AH10) -> 0 | AK10: TE CRISTAL | AL10: 1.5 | AN10: =AM10*AL10 -> 0 | AP10: TE LIPTON | AQ10: 2 | AS10: =AR10*AQ10 -> 0
AD11: =SUM(AD7:AD10) -> 22 | AK11: GATORADE | AL11: 3 | AN11: =AM11*AL11 -> 0 | AP11: VITA TE | AQ11: 1.5 | AS11: =AR11*AQ11 -> 0
AK12: MALTA | AL12: 2.6 | AN12: =AM12*AL12 -> 0 | AS12: =AR12*AQ12 -> 0
AK13: SODA | AL13: 1 | AM13: 1 | AN13: =AM13*AL13 -> 1 | AS13: =AR13*AQ13 -> 0
AK14: CAROREÑA | AL14: 2 | AN14: =AM14*AL14 -> 0 | AS14: =AR14*AQ14 -> 0
AK15: CERVEZA POLAR | AL15: 2 | AN15: =AM15*AL15 -> 0 | AS15: =AR15*AQ15 -> 0
AK16: SOLERA | AL16: 1.5 | AN16: =AM16*AL16 -> 0 | AS16: =AR16*AQ16 -> 0
AK17: PACK POLAR | AL17: 6 | AM17: 1 | AN17: =AM17*AL17 -> 6 | AS17: =AR17*AQ17 -> 0
B18: =SUM(B7:B15) -> 1 | C18: =SUM(C7:C15) -> 1 | D18: =SUM(D7:D15) -> 2 | E18: =SUM(E7:E15) -> 1 | F18: =SUM(F7:F15) -> 3 | G18: =SUM(G7:G15) -> 2 | H18: =SUM(H7:H15) -> 2 | I18: =SUM(I7:I15) -> 1 | ... AC18: =SUM(AC7:AC15) -> 0 | AK18: DORITO PEQ | AL18: 2 | AN18: =AM18*AL18 -> 0 | AS18: =AR18*AQ18 -> 0
AK19: DORITO MED | AL19: 4 | AN19: =AM19*AL19 -> 0 | AS19: =AR19*AQ19 -> 0
B20: PERNOCTA | AK20: CHEESE TREE PEQ | AL20: 2 | AN20: =AM20*AL20 -> 0 | AS20: =AR20*AQ20 -> 0
A21: TIPO DE HABITACION | B21: M | C21: M | D21: M | E21: M | F21: M | G21: M | H21: M | I21: M | J21: M | K21: M | L21: M | M21: M | AK21: CHEESE TREE MED | AL21: 3 | AN21: =AM21*AL21 -> 0 | AS21: =AR21*AQ21 -> 0
B22: 1 | C22: 2 | D22: 3 | E22: 4 | F22: 5 | G22: 6 | H22: 7 | I22: 8 | J22: 9 | K22: 10 | L22: 11 | M22: 12 | AD22: TTAL HB | AE22: HRAS EXTRAS | AI22: TTAL H EXT | AK22: PEPITO FIRTOLAY | AL22: 1 | AN22: =AM22*AL22 -> 0 | AS22: =AR22*AQ22 -> 0
A23: MATRINONIAL | C23: 1 | D23: 1 | AD23: =+C34+D34+F34+J34+L34+M34 -> 2 | AI23: =SUM(AE23:AH23) -> 0 | AK23: TOSTON TOM | AL23: 2 | AN23: =AM23*AL23 -> 0 | AS23: =AR23*AQ23 -> 0
A24: MINI SUITE | AD24: =+B34+E34+G34+H34+I34+K34 -> 0 | AI24: =SUM(AE24:AH24) -> 0 | AK24: COCOSSETE | AL24: 2 | AN24: =AM24*AL24 -> 0 | AS24: =AR24*AQ24 -> 0
AI25: =SUM(AE25:AH25) -> 0 | AK25: SAMBA | AL25: 2 | AN25: =AM25*AL25 -> 0 | AS25: =AR25*AQ25 -> 0
AD26: =R34+S34 -> 0 | AI26: =SUM(AE26:AH26) -> 0 | AK26: FREGELL | AL26: 1 | AN26: =AM26*AL26 -> 0 | AS26: =AR26*AQ26 -> 0
AD27: =SUM(AD23:AD26) -> 2 | AN27: =SUM(AN3:AN26) -> 7 | AS27: =SUM(AS3:AS26) -> 0
AK29: DAÑOS, SERVICIOS Y EXTRAS
AK30: DESINFECCION | AL30: 4 | AN30: =AM30*AL30 -> 0
AK31: DAÑOS | AL31: 5 | AN31: =AM31*AL31 -> 0
AK32: SERV LAV X PIEZA | AL32: 1 | AN32: =AM32*AL32 -> 0
AK33: DECORACION MOD 1 | AL33: 5 | AN33: =AM33*AL33 -> 0
B34: =SUM(B23:B31) -> 0 | C34: =SUM(C23:C31) -> 1 | D34: =SUM(D23:D31) -> 1 | E34: =SUM(E23:E31) -> 0 | F34: =SUM(F23:F31) -> 0 | G34: =SUM(G23:G31) -> 0 | H34: =SUM(H23:H31) -> 0 | I34: =SUM(I23:I31) -> 0 | ... AC34: =SUM(AC23:AC31) -> 0 | AK34: DECORACION MOD 2 | AL34: 5 | AN34: =AM34*AL34 -> 0
AK35: DECORACION MOD 3 | AL35: 5 | AN35: =AM35*AL35 -> 0
A36: CUADRE DE CAJA | O36: SENCILLA | S36: PERNOCTA | Z36: TOTAL HABITACIÓN | AF36: =O42+S42 -> 24 | AK36: OTROS DAÑOS | AL36: 5 | AN36: =AM36*AL36 -> 0
A37: HABITACIÓN | D37: SENCILLA | F37: HORAS ADICIONAL | H37: PERNOTA | L37: HABITACIÓN | O37: CANTID. HAB | Q37: HORAS ADIC | S37: CANTID. HAB | U37: VENTA | Z37: TOTAL VENTA HOTEL | AF37: =U42 -> 276 | AN37: =SUM(AN30:AN36) -> 0
A38: MATRINONIAL | D38: 10 | F38: 2.5 | H38: 20 | L38: MATRINONIAL | O38: =AD7 -> 14 | Q38: =AI7+AI23 -> 0 | S38: =AD23 -> 2 | U38: =S38*H38+O38*D38+Q38*F38 -> 180 | Z38: ACOMPAÑATE | AF38: =AN39 -> 0
A39: MINI SUITE | D39: 12 | F39: 3 | H39: 24 | L39: MINI SUITE | O39: =AD8 -> 8 | Q39: =AI8 -> 0 | S39: =AD24 -> 0 | U39: =S39*H39+O39*D39+Q39*F39 -> 96 | Z39: DAÑOS, SERV Y OTROS | AF39: =AN37 -> 0 | AK39: ACOMPAÑANTE | AL39: 5 | AN39: =AM39*AL39 -> 0
O40: =AD9 -> 0 | Q40: =AI9 -> 0 | S40: =AD25 -> 0 | U40: =S40*H40+O40*D40+Q40*F40 -> 0 | Z40: MINI BAR | AF40: =+AN27+AS27 -> 7
O41: =AD10 -> 0 | Q41: =AI10 -> 0 | S41: =AD26 -> 0 | U41: =S41*H41+O41*D41+Q41*F41 -> 0 | Z41: TOTAL VENTA HOTEL | AF41: =SUM(AF37:AF40) -> 283
...

Sheet CIERRE JUEVES
A1: *
C4: TASA INTERNA
D5: =+JUEVES!P2 -> 890
B6: 45758
B7: =JUEVES!F1 -> 46241
B8: TOTAL HABITACIONES | C8: =JUEVES!AF36 -> 24
B9: VENTAS HABITACIONES | C9: =JUEVES!AF37*JUEVES!P2 -> 245640 | D9: =+C9/D5 -> 276
B10: INGRESO DE ACOMPAÑANTE | C10: =+JUEVES!AF38*'CIERRE JUEVES'!D5 -> 0 | D10: =C10/D5 -> 0
B11: VENTAS MINI BAR | C11: =JUEVES!AF40*JUEVES!P2 -> 6230 | D11: =+C11/D5 -> 7
B12: DAÑOS, SERV Y OTROS | C12: =+JUEVES!AF39*'CIERRE JUEVES'!D5 -> 0 | D12: =C12/D5 -> 0
D13: =+C13/D5 -> 0
B15: TOTAL VENTAS | C15: =SUM(C9:C14) -> 251870 | D15: =+C15/D5 -> 283
B17: DISPONIBLE
B18: DESCRIPCION | C18: DESGLOSE | D18: INGRESO REAL DIARIO
B19: DIVISAS | C19: =JUEVES!K51 -> 136 | D19: =+C19 -> 136
B20: EFECTIVO BSS | C20: =JUEVES!F51 -> 13800 | D20: =+C20/D5 -> 15.505618
B21: TRANSF / PAGO MOVIL | C21: =JUEVES!S46 -> 117150 | D21: =+C21/D5 -> 131.62921
B22: ZELLE
B23: EFECTIVO $ | C23: =+C19 -> 136 | D23: =SUM(D19:D22) -> 283.13483
B24: EFECTIVO BS | C24: =+C20 -> 13800 | D24: =D23-D15 -> 0.13483146
B26: EGRESOS | C26: BS | D26: $
C32: =SUM(C27:C31) -> 0 | D32: =SUM(D27:D31) -> 0
B34: EFECTIVO VENTA DIARIA BS | C34: =+C24 -> 13800
B35: EFECTIVO VENTA DIARIA $ | C35: =+C23 -> 136
B36: EGRESOS BS | C36: =+C32 -> 0
B37: EGRESOS $ | C37: =+D32 -> 0
B38: TOTAL A ENTREGAR $ | C38: =+C35-C37 -> 136
B39: TOTAL ENTREGAR BS EFEC | C39: =+C34-C36 -> 13800
B41: OBSERVACION: SOBRANTE DE 0,5 POR VUELTO

Sheet CIERRE DE LUN A JUE
G5: TASA LUNES | H5: TASA MARTES | I5: TASA MIERCOLES | J5: TASA JUEVES
B6: 45758
G7: ='CIERRE LUNES'!D5 -> 890 | H7: ='CIERRE MARTES'!D5 -> 890 | I7: ='CIERRE MIERCOLES'!D5 -> 890 | J7: ='CIERRE JUEVES'!D5 -> 890
B8: TOTAL HABITACIONES | C8: ='CIERRE LUNES'!C8+'CIERRE MARTES'!C8+'CIERRE MIERCOLES'!C8+'CIERRE JUEVES'!C8 -> 95
B9: VENTAS HABITACIONES LUNES | C9: ='CIERRE LUNES'!C9 -> 277680 | D9: =+C9/G7 -> 312
B10: VENTAS HABITACIONES MARTES | C10: ='CIERRE MARTES'!C9 -> 288360 | D10: =+C10/H7 -> 324
B11: VENTAS HABITACIONES MIERCOLES | C11: =+'CIERRE MIERCOLES'!C9 -> 215380 | D11: =+C11/I7 -> 242
B12: VENTAS HABITACIONES JUEVES | C12: =+'CIERRE JUEVES'!C9 -> 245640 | D12: =+C12/J7 -> 276
B13: INGRESO DE ACOMPAÑANTE LUNES | C13: =+'CIERRE LUNES'!C10 -> 0 | D13: =+C13/G7 -> 0
B14: INGRESO DE ACOMPAÑANTE MARTES | C14: =+'CIERRE MARTES'!C10 -> 0 | D14: =+C14/H7 -> 0
B15: INGRESO DE ACOMPAÑANTE MIERCOLES | C15: =+'CIERRE MIERCOLES'!C10 -> 0 | D15: =+C15/I7 -> 0
B16: INGRESO DE ACOMPAÑANTE JUEVES | C16: =+'CIERRE JUEVES'!C10 -> 0 | D16: =+C16/J7 -> 0
B17: VENTAS MINI BAR LUNES | C17: ='CIERRE LUNES'!C11 -> 8455 | D17: =+C17/G7 -> 9.5
B18: VENTAS MINI BAR MARTES | C18: =+'CIERRE MARTES'!C11 -> 15575 | D18: =+C18/H7 -> 17.5
B19: VENTAS MINI BAR MIERCOLES | C19: =+'CIERRE MIERCOLES'!C11 -> 12460 | D19: =+C19/I7 -> 14 | G19: EFECTIVO | K19: DIVISA
B20: VENTAS MINI BAR JUEVES | C20: =+'CIERRE JUEVES'!C11 -> 6230 | D20: =+C20/J7 -> 7 | G20: 10 | I20: =H20*G20 -> 0 | K20: 1 | M20: =L20*K20 -> 0
B21: DAÑOS, SERV Y OTROS LUNES | C21: =+'CIERRE LUNES'!C12 -> 0 | D21: =+C21/G7 -> 0 | G21: 20 | I21: =H21*G21 -> 0 | K21: 5 | M21: =L21*K21 -> 0
B22: DAÑOS, SERV Y OTROS MARTES | C22: =+'CIERRE MARTES'!C12 -> 0 | D22: =+C22/H7 -> 0 | G22: 50 | I22: =H22*G22 -> 0 | K22: 10 | M22: =L22*K22 -> 0
B23: DAÑOS, SERV Y OTROS MIERCOLES | C23: =+'CIERRE MIERCOLES'!C12 -> 0 | D23: =+C23/I7 -> 0 | G23: 100 | I23: =H23*G23 -> 0 | K23: 20 | M23: =L23*K23 -> 0
B24: DAÑOS, SERV Y OTROS JUEVES | C24: =+'CIERRE JUEVES'!C12 -> 0 | D24: =+C24/J7 -> 0 | G24: 200 | I24: =H24*G24 -> 0 | K24: 50 | M24: =L24*K24 -> 0
G25: 500 | I25: =H25*G25 -> 0 | K25: 100 | M25: =L25*K25 -> 0
B26: TOTAL VENTAS | C26: =SUM(C9:C25) -> 1069780 | D26: =+D9+D10+D11+D12+D13+D14+D15+D16+D17+D18+D19+D20+D21+D22+D23+D24 -> 1202 | I26: =SUM(I20:I25) -> 0 | M26: =SUM(M20:M25) -> 0
B28: DESCRIPCION | C28: DESGLOSE | D28: INGRESO REAL DIARIO
B29: DIVISAS | C29: ='CIERRE LUNES'!C23+'CIERRE MARTES'!C23+'CIERRE MIERCOLES'!C23+'CIERRE JUEVES'!C19 -> 568 | D29: =+C29 -> 568
B30: EFECTIVO BSS LUNES | C30: ='CIERRE LUNES'!C24 -> 1800 | D30: =+C30/G7 -> 2.0224719
B31: EFECTIVO BSS MARTES | C31: =+'CIERRE MARTES'!C24 -> 4040 | D31: =+C31/H7 -> 4.5393258
B32: EFECTIVO BSS MIERCOLES | D32: =+C32/I7 -> 0
B33: EFECTIVO BSS JUEVES | C33: =+'CIERRE MIERCOLES'!C24+'CIERRE JUEVES'!C24 -> 36940 | D33: =+C33/J7 -> 41.505618
B34: PUNTO VENTA
B35: TRANSF / PAGO MOVIL LUNES | C35: ='CIERRE LUNES'!C21 -> 179315 | D35: =+C35/G7 -> 201.47753
B36: TRANSF / PAGO MOVIL MARTES | C36: ='CIERRE MARTES'!C21 -> 153920 | D36: =+C36/H7 -> 172.94382
B37: TRANSF / PAGO MOVIL MIERCOLES | C37: =+'CIERRE MIERCOLES'!C21 -> 90780 | D37: =+C37/I7 -> 102
B38: TRANSF / PAGO MOVIL JUEVES | C38: =+'CIERRE JUEVES'!C21 -> 117150 | D38: =+C38/J7 -> 131.62921
B39: ZELLE
B40: CAMBIO BS X $
B41: CAMBIO $ X BSS
B42: EFECTIVO $ | C42: =+C29+D40 -> 568 | D42: =SUM(D29:D41) -> 1224.118
B43: EFECTIVO BS | C43: =C30+C31+C33-C41 -> 42780 | D43: =+D42-D26 -> 22.117978
B44: TOTAL PAGO MOVIL Y PDV | C44: =+C35+C36+C37+C38 -> 541165
B45: EGRESOS | C45: BS | D45: $
...

Sheet VIERNES
C1: FECHA | F1: 46242 | K1: TURNO | M1: DIURNO & NOCTURNO | AK1: MINI BAR | AP1: MINI BAR
C2: RESPONSABLE | F2: HILDA | M2: $ TASA | P2: 890 | AK2: DESCRIPCIÓN | AL2: PRECIO | AM2: CANT # 1 | AN2: TOTAL VENTA | AP2: DESCRIPCIÓN | AQ2: PRECIO | AR2: CANT # 1 | AS2: TOTAL VENTA
AK3: AGUA PEQUEÑA | AL3: 1 | AN3: =AM3*AL3 -> 0 | AP3: SUPER POPY | AQ3: 2 | AS3: =AR3*AQ3 -> 0
B4: SENCILLA | AK4: AGUA MEDIANA | AL4: 2 | AM4: 1 | AN4: =AM4*AL4 -> 2 | AP4: GALAK | AQ4: 2.5 | AS4: =AR4*AQ4 -> 0
A5: TIPO DE HABITACION | B5: M | C5: M | D5: M | E5: M | F5: M | G5: M | H5: M | I5: M | J5: M | K5: M | L5: M | M5: M | AK5: MINI REFRESCO | AL5: 1.5 | AN5: =AM5*AL5 -> 0 | AP5: OREO | AQ5: 1 | AS5: =AR5*AQ5 -> 0
B6: 1 | C6: 2 | D6: 3 | E6: 4 | F6: 5 | G6: 6 | H6: 7 | I6: 8 | J6: 9 | K6: 10 | L6: 11 | M6: 12 | AD6: TTAL HB | AE6: HRAS EXTRAS | AI6: TTAL H EXT | AK6: REFRESCO 1 LTS | AL6: 2 | AM6: 2 | AN6: =AM6*AL6 -> 4 | AP6: GALLETA CLUB | AQ6: 1 | AS6: =AR6*AQ6 -> 0
A7: MATRINONIAL | B7: 1 | C7: 1 | D7: 1 | E7: 1 | F7: 1 | G7: 1 | H7: 1 | I7: 1 | J7: 1 | M7: 1 | AD7: =+C18+D18+F18+J18+K18+L18+M18 -> 13 | AE7: 1 | AI7: =SUM(AE7:AH7) -> 1 | AK7: POWER 400ML | AL7: 1 | AN7: =AM7*AL7 -> 0 | AP7: BOM BOM BUM | AQ7: 0.3 | AR7: 1 | AS7: =AR7*AQ7 -> 0.3
A8: MINI SUITE | C8: 1 | D8: 1 | E8: 1 | F8: 1 | G8: 1 | H8: 1 | I8: 1 | J8: 1 | AD8: =+B18+E18+G18+H18+I18+K18 -> 14 | AE8: 4 | AI8: =SUM(AE8:AH8) -> 4 | AK8: ROCKSTAR | AL8: 2 | AN8: =AM8*AL8 -> 0 | AP8: JABON DE BAÑO | AQ8: 2 | AS8: =AR8*AQ8 -> 0
C9: 1 | D9: 1 | E9: 1 | G9: 1 | I9: 1 | AI9: =SUM(AE9:AH9) -> 0 | AK9: REDBULL | AL9: 4.5 | AN9: =AM9*AL9 -> 0 | AP9: PRESERVATIVO | AQ9: 1 | AR9: 2 | AS9: =AR9*AQ9 -> 2
D10: 1 | E10: 1 | G10: 1 | AI10: =SUM(AE10:AH10) -> 0 | AK10: TE CRISTAL | AL10: 1.5 | AN10: =AM10*AL10 -> 0 | AP10: TE LIPTON | AQ10: 2 | AS10: =AR10*AQ10 -> 0
D11: 1 | AD11: =SUM(AD7:AD10) -> 27 | AK11: GATORADE | AL11: 3 | AM11: 1 | AN11: =AM11*AL11 -> 3 | AP11: VITA TE | AQ11: 1.5 | AS11: =AR11*AQ11 -> 0
AK12: MALTA | AL12: 2 | AM12: 1 | AN12: =AM12*AL12 -> 2 | AP12: NUCITA | AQ12: 2 | AR12: 1 | AS12: =AR12*AQ12 -> 2
AK13: SODA | AL13: 1 | AN13: =AM13*AL13 -> 0 | AS13: =AR13*AQ13 -> 0
AK14: CAROREÑA | AL14: 2 | AN14: =AM14*AL14 -> 0 | AS14: =AR14*AQ14 -> 0
AK15: CERVEZA POLAR | AL15: 2 | AN15: =AM15*AL15 -> 0 | AS15: =AR15*AQ15 -> 0
AK16: SOLERA | AL16: 1.5 | AN16: =AM16*AL16 -> 0 | AS16: =AR16*AQ16 -> 0
AK17: PACK POLAR | AL17: 6 | AM17: 1 | AN17: =AM17*AL17 -> 6 | AS17: =AR17*AQ17 -> 0
B18: =SUM(B7:B15) -> 1 | C18: =SUM(C7:C15) -> 3 | D18: =SUM(D7:D15) -> 5 | E18: =SUM(E7:E15) -> 4 | F18: =SUM(F7:F15) -> 2 | G18: =SUM(G7:G15) -> 4 | H18: =SUM(H7:H15) -> 2 | I18: =SUM(I7:I15) -> 3 | ... AC18: =SUM(AC7:AC15) -> 0 | AK18: DORITO PEQ | AL18: 2 | AM18: 1 | AN18: =AM18*AL18 -> 2 | AS18: =AR18*AQ18 -> 0
AK19: DORITO MED | AL19: 4 | AN19: =AM19*AL19 -> 0 | AS19: =AR19*AQ19 -> 0
B20: PERNOCTA | AK20: CHEESE TREE PEQ | AL20: 2 | AN20: =AM20*AL20 -> 0 | AS20: =AR20*AQ20 -> 0
A21: TIPO DE HABITACION | B21: M | C21: M | D21: M | E21: M | F21: M | G21: M | H21: M | I21: M | J21: M | K21: M | L21: M | M21: M | AK21: CHEESE TREE MED | AL21: 3 | AN21: =AM21*AL21 -> 0 | AS21: =AR21*AQ21 -> 0
B22: 1 | C22: 2 | D22: 3 | E22: 4 | F22: 5 | G22: 6 | H22: 7 | I22: 8 | J22: 9 | K22: 10 | L22: 11 | M22: 12 | AD22: TTAL HB | AE22: HRAS EXTRAS | AI22: TTAL H EXT | AK22: PEPITO FIRTOLAY | AL22: 1 | AN22: =AM22*AL22 -> 0 | AS22: =AR22*AQ22 -> 0
A23: MATRINONIAL | C23: 1 | H23: 1 | L23: 1 | M23: 1 | AD23: =+C34+D34+F34+J34+L34+M34 -> 3 | AI23: =SUM(AE23:AH23) -> 0 | AK23: TOSTON TOM | AL23: 2 | AN23: =AM23*AL23 -> 0 | AS23: =AR23*AQ23 -> 0
A24: MINI SUITE | AD24: =+B34+E34+G34+H34+I34+K34 -> 1 | AI24: =SUM(AE24:AH24) -> 0 | AK24: COCOSSETE | AL24: 2 | AN24: =AM24*AL24 -> 0 | AS24: =AR24*AQ24 -> 0
AI25: =SUM(AE25:AH25) -> 0 | AK25: SAMBA | AL25: 2 | AN25: =AM25*AL25 -> 0 | AS25: =AR25*AQ25 -> 0
AI26: =SUM(AE26:AH26) -> 0 | AK26: FREGELL | AL26: 1 | AN26: =AM26*AL26 -> 0 | AS26: =AR26*AQ26 -> 0
AD27: =SUM(AD23:AD26) -> 4 | AN27: =SUM(AN3:AN26) -> 19 | AS27: =SUM(AS3:AS26) -> 4.3
AK29: DAÑOS, SERVICIOS Y EXTRAS
AK30: DESINFECCION | AL30: 4 | AN30: =AM30*AL30 -> 0
AK31: DAÑOS | AL31: 5 | AN31: =AM31*AL31 -> 0
AK32: SERV LAV X PIEZA | AL32: 1 | AN32: =AM32*AL32 -> 0
AK33: DECORACION MOD 1 | AL33: 5 | AN33: =AM33*AL33 -> 0
B34: =SUM(B23:B31) -> 0 | C34: =SUM(C23:C31) -> 1 | D34: =SUM(D23:D31) -> 0 | E34: =SUM(E23:E31) -> 0 | F34: =SUM(F23:F31) -> 0 | G34: =SUM(G23:G31) -> 0 | H34: =SUM(H23:H31) -> 1 | I34: =SUM(I23:I31) -> 0 | ... AC34: =SUM(AC23:AC31) -> 0 | AK34: DECORACION MOD 2 | AL34: 5 | AN34: =AM34*AL34 -> 0
AK35: DECORACION MOD 3 | AL35: 5 | AN35: =AM35*AL35 -> 0
A36: CUADRE DE CAJA | O36: SENCILLA | S36: PERNOCTA | Z36: TOTAL HABITACIÓN | AF36: =O42+S42 -> 31 | AK36: OTROS DAÑOS | AL36: 5 | AN36: =AM36*AL36 -> 0
A37: HABITACIÓN | D37: SENCILLA | F37: HORAS ADICIONAL | H37: PERNOTA | L37: HABITACIÓN | O37: CANTID. HAB | Q37: HORAS ADIC | S37: CANTID. HAB | U37: VENTA | Z37: TOTAL VENTA HOTEL | AF37: =U42 -> 396.5 | AN37: =SUM(AN30:AN36) -> 0
A38: MATRINONIAL | D38: 10 | F38: 2.5 | H38: 20 | L38: MATRINONIAL | O38: =AD7 -> 13 | Q38: =AI7 -> 1 | S38: =AD23 -> 3 | U38: =S38*H38+O38*D38+Q38*F38 -> 192.5 | Z38: ACOMPAÑATE | AF38: =AN39 -> 0
A39: MINI SUITE | D39: 12 | F39: 3 | H39: 24 | L39: MINI SUITE | O39: =AD8 -> 14 | Q39: =AI8 -> 4 | S39: =AD24 -> 1 | U39: =S39*H39+O39*D39+Q39*F39 -> 204 | Z39: DAÑOS, SERV Y OTROS | AF39: =AN37 -> 0 | AK39: ACOMPAÑANTE | AL39: 5 | AN39: =AM39*AL39 -> 0
O40: =AD9 -> 0 | Q40: =AI9 -> 0 | S40: =AD25 -> 0 | U40: =S40*H40+O40*D40+Q40*F40 -> 0 | Z40: MINI BAR | AF40: =+AN27+AS27 -> 23.3
O41: =AD10 -> 0 | Q41: =AI10 -> 0 | S41: =AD26 -> 0 | U41: =S41*H41+O41*D41+Q41*F41 -> 0 | Z41: TOTAL VENTA HOTEL | AF41: =SUM(AF37:AF40) -> 419.8
...

Sheet CIERRE VIERNES
A1: *
C4: TASA INTERNA
D5: =+VIERNES!P2 -> 890
B6: 45758
B7: =VIERNES!F1 -> 46242
B8: TOTAL HABITACIONES | C8: =VIERNES!AF36 -> 31
B9: VENTAS HABITACIONES | C9: =VIERNES!AF37*VIERNES!P2 -> 352885 | D9: =+C9/D5 -> 396.5
B10: INGRESO DE ACOMPAÑANTE | C10: =+VIERNES!AF38*'CIERRE VIERNES'!D5 -> 0 | D10: =C10/D5 -> 0
B11: VENTAS MINI BAR | C11: =VIERNES!AF40*VIERNES!P2 -> 20737 | D11: =+C11/D5 -> 23.3
B12: DAÑOS, SERV Y OTROS | C12: =+VIERNES!AF39*'CIERRE VIERNES'!D5 -> 0 | D12: =C12/D5 -> 0
D13: =+C13/D5 -> 0
B15: TOTAL VENTAS | C15: =SUM(C9:C14) -> 373622 | D15: =+C15/D5 -> 419.8
B17: DISPONIBLE
B18: DESCRIPCION | C18: DESGLOSE | D18: INGRESO REAL DIARIO
B19: DIVISAS | C19: =VIERNES!K51 -> 157 | D19: =+C19 -> 157
B20: EFECTIVO BSS | C20: =VIERNES!F51 -> 11680 | D20: =+C20/D5 -> 13.123596
B21: TRANSF / PAGO MOVIL | C21: =VIERNES!S46 -> 222322 | D21: =+C21/D5 -> 249.8
B22: ZELLE
B23: EFECTIVO $ | C23: =+C19 -> 157 | D23: =SUM(D19:D22) -> 419.9236
B24: EFECTIVO BS | C24: =+C20 -> 11680 | D24: =D23-D15 -> 0.12359551
B26: EGRESOS | C26: BS | D26: $
C32: =SUM(C27:C31) -> 0 | D32: =SUM(D27:D31) -> 0
B34: EFECTIVO VENTA DIARIA BS | C34: =+C24 -> 11680
B35: EFECTIVO VENTA DIARIA $ | C35: =+C23 -> 157
B36: EGRESOS BS | C36: =+C32 -> 0
B37: EGRESOS $ | C37: =+D32 -> 0
B38: TOTAL A ENTREGAR $ | C38: =+C35-C37 -> 157
B39: TOTAL ENTREGAR BS EFEC | C39: =+C34-C36 -> 11680
B41: OBSERVACION:

Sheet SABADO
C1: FECHA | F1: 46242 | K1: TURNO | M1: DIURNO & NOCTURNO | AK1: MINI BAR | AP1: MINI BAR
C2: RESPONSABLE | F2: DAI | M2: $ TASA | P2: 890 | AK2: DESCRIPCIÓN | AL2: PRECIO | AM2: CANT # 1 | AN2: TOTAL VENTA | AP2: DESCRIPCIÓN | AQ2: PRECIO | AR2: CANT # 1 | AS2: TOTAL VENTA
AK3: AGUA PEQUEÑA | AL3: 1 | AN3: =AM3*AL3 -> 0 | AP3: SUPER POPY | AQ3: 2 | AS3: =AR3*AQ3 -> 0
B4: SENCILLA | AK4: AGUA MEDIANA | AL4: 2 | AM4: 5 | AN4: =AM4*AL4 -> 10 | AP4: GALAK | AQ4: 2.5 | AR4: 1 | AS4: =AR4*AQ4 -> 2.5
A5: TIPO DE HABITACION | B5: M | C5: M | D5: M | E5: M | F5: M | G5: M | H5: M | I5: M | J5: M | K5: M | L5: M | M5: M | AK5: MINI REFRESCO | AL5: 1.5 | AN5: =AM5*AL5 -> 0 | AP5: OREO | AQ5: 1 | AS5: =AR5*AQ5 -> 0
B6: 1 | C6: 2 | D6: 3 | E6: 4 | F6: 5 | G6: 6 | H6: 7 | I6: 8 | J6: 9 | K6: 10 | L6: 11 | M6: 12 | AD6: TTAL HB | AE6: HRAS EXTRAS | AI6: TTAL H EXT | AK6: REFRESCO 1 LTS | AL6: 2 | AM6: 3 | AN6: =AM6*AL6 -> 6 | AP6: GALLETA CLUB | AQ6: 1 | AS6: =AR6*AQ6 -> 0
A7: MATRINONIAL | B7: 1 | C7: 1 | D7: 1 | E7: 1 | F7: 1 | G7: 1 | H7: 1 | J7: 1 | K7: 1 | L7: 1 | AD7: =+C18+D18+F18+J18+L18+M18 -> 21 | AE7: 4 | AI7: =SUM(AE7:AH7) -> 4 | AK7: POWER 400ML | AL7: 1 | AN7: =AM7*AL7 -> 0 | AP7: BOM BOM BUM | AQ7: 0.3 | AS7: =AR7*AQ7 -> 0
A8: MINI SUITE | B8: 1 | C8: 1 | D8: 1 | E8: 1 | G8: 1 | H8: 1 | J8: 1 | K8: 1 | L8: 1 | AD8: =+B18+E18+G18+H18+I18+K18 -> 18 | AI8: =SUM(AE8:AH8) -> 0 | AK8: ROCKSTAR | AL8: 2 | AN8: =AM8*AL8 -> 0 | AP8: JABON DE BAÑO | AQ8: 2 | AS8: =AR8*AQ8 -> 0
B9: 1 | C9: 1 | D9: 1 | G9: 1 | J9: 1 | K9: 1 | L9: 1 | AI9: =SUM(AE9:AH9) -> 0 | AK9: REDBULL | AL9: 4.5 | AN9: =AM9*AL9 -> 0 | AP9: PRESERVATIVO | AQ9: 1 | AR9: 3 | AS9: =AR9*AQ9 -> 3
B10: 1 | C10: 1 | G10: 1 | J10: 1 | L10: 1 | AI10: =SUM(AE10:AH10) -> 0 | AK10: TE CRISTAL | AL10: 1.5 | AN10: =AM10*AL10 -> 0 | AP10: TE LIPTON | AQ10: 2 | AS10: =AR10*AQ10 -> 0
C11: 1 | G11: 1 | J11: 1 | L11: 1 | AD11: =SUM(AD7:AD10) -> 39 | AK11: GATORADE | AL11: 3 | AM11: 6 | AN11: =AM11*AL11 -> 18 | AP11: VITA TE | AQ11: 1.5 | AS11: =AR11*AQ11 -> 0
C12: 1 | G12: 1 | L12: 1 | AK12: MALTA | AL12: 2 | AM12: 1 | AN12: =AM12*AL12 -> 2 | AS12: =AR12*AQ12 -> 0
G13: 1 | AK13: SODA | AL13: 1 | AN13: =AM13*AL13 -> 0 | AS13: =AR13*AQ13 -> 0
AK14: CAROREÑA | AL14: 2 | AN14: =AM14*AL14 -> 0 | AS14: =AR14*AQ14 -> 0
AK15: CERVEZA POLAR | AL15: 2 | AM15: 2 | AN15: =AM15*AL15 -> 4 | AS15: =AR15*AQ15 -> 0
AK16: SOLERA | AL16: 1.5 | AN16: =AM16*AL16 -> 0 | AS16: =AR16*AQ16 -> 0
AK17: PACK POLAR | AL17: 6 | AM17: 2 | AN17: =AM17*AL17 -> 12 | AS17: =AR17*AQ17 -> 0
B18: =SUM(B7:B15) -> 4 | C18: =SUM(C7:C15) -> 6 | D18: =SUM(D7:D15) -> 3 | E18: =SUM(E7:E15) -> 2 | F18: =SUM(F7:F15) -> 1 | G18: =SUM(G7:G15) -> 7 | H18: =SUM(H7:H15) -> 2 | I18: =SUM(I7:I15) -> 0 | ... AC18: =SUM(AC7:AC15) -> 0 | AK18: DORITO PEQ | AL18: 2 | AM18: 3 | AN18: =AM18*AL18 -> 6 | AS18: =AR18*AQ18 -> 0
AK19: DORITO MED | AL19: 4 | AN19: =AM19*AL19 -> 0 | AS19: =AR19*AQ19 -> 0
B20: PERNOCTA | AK20: CHEESE TREE PEQ | AL20: 2 | AM20: 1 | AN20: =AM20*AL20 -> 2 | AS20: =AR20*AQ20 -> 0
A21: TIPO DE HABITACION | B21: M | C21: M | D21: M | E21: M | F21: M | G21: M | H21: M | I21: M | J21: M | K21: M | L21: M | M21: M | AK21: CHEESE TREE MED | AL21: 3 | AN21: =AM21*AL21 -> 0 | AS21: =AR21*AQ21 -> 0
B22: 1 | C22: 2 | D22: 3 | E22: 4 | F22: 5 | G22: 6 | H22: 7 | I22: 8 | J22: 9 | K22: 10 | L22: 11 | M22: 12 | AD22: TTAL HB | AE22: HRAS EXTRAS | AI22: TTAL H EXT | AK22: PEPITO FIRTOLAY | AL22: 1 | AN22: =AM22*AL22 -> 0 | AS22: =AR22*AQ22 -> 0
A23: MATRINONIAL | D23: 1 | E23: 1 | F23: 1 | H23: 1 | I23: 1 | M23: 1 | AD23: =+C34+D34+F34+J34+L34+M34 -> 3 | AI23: =SUM(AE23:AH23) -> 0 | AK23: TOSTON TOM | AL23: 2 | AN23: =AM23*AL23 -> 0 | AS23: =AR23*AQ23 -> 0
A24: MINI SUITE | AD24: =+B34+E34+G34+H34+I34+K34 -> 3 | AI24: =SUM(AE24:AH24) -> 0 | AK24: COCOSSETE | AL24: 2 | AM24: 1 | AN24: =AM24*AL24 -> 2 | AS24: =AR24*AQ24 -> 0
AI25: =SUM(AE25:AH25) -> 0 | AK25: SAMBA | AL25: 2 | AN25: =AM25*AL25 -> 0 | AS25: =AR25*AQ25 -> 0
AI26: =SUM(AE26:AH26) -> 0 | AK26: FREGELL | AL26: 1 | AM26: 2 | AN26: =AM26*AL26 -> 2 | AS26: =AR26*AQ26 -> 0
AD27: =SUM(AD23:AD26) -> 6 | AN27: =SUM(AN3:AN26) -> 64 | AS27: =SUM(AS3:AS26) -> 5.5
AK29: DAÑOS, SERVICIOS Y EXTRAS
AK30: DESINFECCION | AL30: 5 | AN30: =AM30*AL30 -> 0
AK31: DAÑOS | AL31: 5 | AN31: =AM31*AL31 -> 0
AK32: SERV LAV X PIEZA | AL32: 1 | AN32: =AM32*AL32 -> 0
AK33: DECORACION MOD 1 | AL33: 5 | AN33: =AM33*AL33 -> 0
B34: =SUM(B23:B31) -> 0 | C34: =SUM(C23:C31) -> 0 | D34: =SUM(D23:D31) -> 1 | E34: =SUM(E23:E31) -> 1 | F34: =SUM(F23:F31) -> 1 | G34: =SUM(G23:G31) -> 0 | H34: =SUM(H23:H31) -> 1 | I34: =SUM(I23:I31) -> 1 | ... AC34: =SUM(AC23:AC31) -> 0 | AK34: DECORACION MOD 2 | AL34: 5 | AN34: =AM34*AL34 -> 0
AK35: DECORACION MOD 3 | AL35: 5 | AN35: =AM35*AL35 -> 0
A36: CUADRE DE CAJA | O36: SENCILLA | S36: PERNOCTA | Z36: TOTAL HABITACIÓN | AF36: =O42+S42 -> 45 | AK36: OTROS DAÑOS | AL36: 5 | AN36: =AM36*AL36 -> 0
A37: HABITACIÓN | D37: SENCILLA | F37: HORAS ADICIONAL | H37: PERNOTA | L37: HABITACIÓN | O37: CANTID. HAB | Q37: HORAS ADIC | S37: CANTID. HAB | U37: VENTA | Z37: TOTAL VENTA HOTEL | AF37: =U42 -> 568 | AN37: =SUM(AN30:AN36) -> 0
A38: MATRINONIAL | D38: 10 | F38: 2.5 | H38: 20 | L38: MATRINONIAL | O38: =AD7 -> 21 | Q38: =AI7+AI23 -> 4 | S38: =AD23 -> 3 | U38: =S38*H38+O38*D38+Q38*F38 -> 280 | Z38: ACOMPAÑATE | AF38: =AN39 -> 0
A39: MINI SUITE | D39: 12 | F39: 3 | H39: 24 | L39: MINI SUITE | O39: =AD8 -> 18 | Q39: =AI8 -> 0 | S39: =AD24 -> 3 | U39: =S39*H39+O39*D39+Q39*F39 -> 288 | Z39: DAÑOS, SERV Y OTROS | AF39: =AN37 -> 0 | AK39: ACOMPAÑANTE | AL39: 5 | AN39: =AM39*AL39 -> 0
O40: =AD9 -> 0 | Q40: =AI9 -> 0 | S40: =AD25 -> 0 | U40: =S40*H40+O40*D40+Q40*F40 -> 0 | Z40: MINI BAR | AF40: =+AN27+AS27 -> 69.5
O41: =AD10 -> 0 | Q41: =AI10 -> 0 | S41: =AD26 -> 0 | U41: =S41*H41+O41*D41+Q41*F41 -> 0 | Z41: TOTAL VENTA HOTEL | AF41: =SUM(AF37:AF40) -> 637.5
...

Sheet CIERRE SABADO
A1: *
C4: TASA INTERNA
D5: =+SABADO!P2 -> 890
B6: 45758
B7: =SABADO!F1 -> 46242
B8: TOTAL HABITACIONES | C8: =SABADO!AF36 -> 45
B9: VENTAS HABITACIONES | C9: =SABADO!AF37*SABADO!P2 -> 505520 | D9: =+C9/D5 -> 568
B10: INGRESO DE ACOMPAÑANTE | C10: =+SABADO!AF38*'CIERRE SABADO'!D5 -> 0 | D10: =C10/D5 -> 0
B11: VENTAS MINI BAR | C11: =SABADO!AF40*SABADO!P2 -> 61855 | D11: =+C11/D5 -> 69.5
B12: DAÑOS, SERV Y OTROS | C12: =SABADO!AF39*SABADO!P2 -> 0 | D12: =C12/D5 -> 0
D13: =+C13/D5 -> 0
B15: TOTAL VENTAS | C15: =SUM(C9:C14) -> 567375 | D15: =+C15/D5 -> 637.5
B17: DISPONIBLE
B18: DESCRIPCION | C18: DESGLOSE | D18: INGRESO REAL DIARIO
B19: DIVISAS | C19: =SABADO!K51 -> 233 | D19: =+C19 -> 233
B20: EFECTIVO BSS | C20: =SABADO!F51 -> 29370 | D20: =+C20/D5 -> 33
B21: TRANSF / PAGO MOVIL | C21: =SABADO!S46 -> 322625 | D21: =+C21/D5 -> 362.5
B22: ZELLE
B23: EFECTIVO $ | C23: =+C19 -> 233 | D23: =SUM(D19:D22) -> 628.5
B24: EFECTIVO BS | C24: =+C20 -> 29370 | D24: =D23-D15 -> -9
B26: EGRESOS | C26: BS | D26: $
C32: =SUM(C27:C31) -> 0 | D32: =SUM(D27:D31) -> 0
B34: EFECTIVO VENTA DIARIA BS | C34: =+C24 -> 29370
B35: EFECTIVO VENTA DIARIA $ | C35: =+C23 -> 233
B36: EGRESOS BS | C36: =+C32 -> 0
B37: EGRESOS $ | C37: =+D32 -> 0
B38: TOTAL A ENTREGAR $ | C38: =+C35-C37 -> 233
B39: TOTAL ENTREGAR BS EFEC | C39: =+C34-C36 -> 29370

Sheet DOMINGO 12
C1: FECHA | F1: 46243 | K1: TURNO | M1: DIURNO & NOCTURNO | AK1: MINI BAR | AP1: MINI BAR
C2: RESPONSABLE | F2: HILDA | M2: $ TASA | P2: 890 | AK2: DESCRIPCIÓN | AL2: PRECIO | AM2: CANT # 1 | AN2: TOTAL VENTA | AP2: DESCRIPCIÓN | AQ2: PRECIO | AR2: CANT # 1 | AS2: TOTAL VENTA
AK3: AGUA PEQUEÑA | AL3: 1 | AN3: =AM3*AL3 -> 0 | AP3: SUPER POPY | AQ3: 2 | AS3: =AR3*AQ3 -> 0
B4: SENCILLA | AK4: AGUA MEDIANA | AL4: 2 | AM4: 4 | AN4: =AM4*AL4 -> 8 | AP4: GALAK | AQ4: 2.5 | AS4: =AR4*AQ4 -> 0
A5: TIPO DE HABITACION | B5: M | C5: M | D5: M | E5: M | F5: M | G5: M | H5: M | I5: M | J5: M | K5: M | L5: M | M5: M | AK5: MINI REFRESCO | AL5: 1.5 | AN5: =AM5*AL5 -> 0 | AP5: OREO | AQ5: 1 | AS5: =AR5*AQ5 -> 0
B6: 1 | C6: 2 | D6: 3 | E6: 4 | F6: 5 | G6: 6 | H6: 7 | I6: 8 | J6: 9 | K6: 10 | L6: 11 | M6: 12 | AD6: TTAL HB | AE6: HRAS EXTRAS | AI6: TTAL H EXT | AK6: REFRESCO 1 LTS | AL6: 2 | AM6: 3 | AN6: =AM6*AL6 -> 6 | AP6: GALLETA CLUB | AQ6: 1 | AR6: 1 | AS6: =AR6*AQ6 -> 1
A7: MATRINONIAL | B7: 1 | C7: 1 | D7: 1 | E7: 1 | F7: 1 | G7: 1 | H7: 1 | I7: 1 | J7: 1 | K7: 1 | L7: 1 | AD7: =+C18+D18+F18+J18+L18+M18 -> 15 | AE7: 4 | AI7: =SUM(AE7:AH7) -> 4 | AK7: POWER 400ML | AL7: 1 | AN7: =AM7*AL7 -> 0 | AP7: BOM BOM BUM | AQ7: 0.3 | AR7: 1 | AS7: =AR7*AQ7 -> 0.3
A8: MINI SUITE | B8: 1 | C8: 1 | D8: 1 | E8: 1 | H8: 1 | I8: 1 | J8: 1 | K8: 1 | L8: 1 | AD8: =+B18+E18+G18+H18+I18+K18 -> 17 | AE8: 2 | AI8: =SUM(AE8:AH8) -> 2 | AK8: ROCKSTAR | AL8: 2 | AN8: =AM8*AL8 -> 0 | AP8: JABON DE BAÑO | AQ8: 2 | AS8: =AR8*AQ8 -> 0
B9: 1 | C9: 1 | D9: 1 | E9: 1 | H9: 1 | I9: 1 | AI9: =SUM(AE9:AH9) -> 0 | AK9: REDBULL | AL9: 4.5 | AN9: =AM9*AL9 -> 0 | AP9: PRESERVATIVO | AQ9: 1 | AS9: =AR9*AQ9 -> 0
B10: 1 | C10: 1 | D10: 1 | AI10: =SUM(AE10:AH10) -> 0 | AK10: TE CRISTAL | AL10: 1.5 | AN10: =AM10*AL10 -> 0 | AP10: TE LIPTON | AQ10: 2 | AR10: 1 | AS10: =AR10*AQ10 -> 2
B11: 1 | C11: 1 | AD11: =SUM(AD7:AD10) -> 32 | AK11: GATORADE | AL11: 3 | AN11: =AM11*AL11 -> 0 | AP11: VITA TE | AQ11: 1.5 | AS11: =AR11*AQ11 -> 0
C12: 1 | AK12: MALTA | AL12: 2.6 | AN12: =AM12*AL12 -> 0 | AS12: =AR12*AQ12 -> 0
AK13: SODA | AL13: 1 | AN13: =AM13*AL13 -> 0 | AS13: =AR13*AQ13 -> 0
AK14: CAROREÑA | AL14: 2 | AN14: =AM14*AL14 -> 0 | AS14: =AR14*AQ14 -> 0
AK15: CERVEZA POLAR | AL15: 2 | AN15: =AM15*AL15 -> 0 | AS15: =AR15*AQ15 -> 0
AK16: SOLERA | AL16: 1.5 | AN16: =AM16*AL16 -> 0 | AS16: =AR16*AQ16 -> 0
AK17: PACK POLAR | AL17: 6 | AM17: 1 | AN17: =AM17*AL17 -> 6 | AS17: =AR17*AQ17 -> 0
B18: =SUM(B7:B15) -> 5 | C18: =SUM(C7:C15) -> 6 | D18: =SUM(D7:D15) -> 4 | E18: =SUM(E7:E15) -> 3 | F18: =SUM(F7:F15) -> 1 | G18: =SUM(G7:G15) -> 1 | H18: =SUM(H7:H15) -> 3 | I18: =SUM(I7:I15) -> 3 | ... AC18: =SUM(AC7:AC15) -> 0 | AK18: DORITO PEQ | AL18: 2 | AM18: 1 | AN18: =AM18*AL18 -> 2 | AS18: =AR18*AQ18 -> 0
AK19: DORITO MED | AL19: 4 | AN19: =AM19*AL19 -> 0 | AS19: =AR19*AQ19 -> 0
B20: PERNOCTA | AK20: CHEESE TREE PEQ | AL20: 2 | AN20: =AM20*AL20 -> 0 | AS20: =AR20*AQ20 -> 0
A21: TIPO DE HABITACION | B21: M | C21: M | D21: M | E21: M | F21: M | G21: M | H21: M | I21: M | J21: M | K21: M | L21: M | M21: M | AK21: CHEESE TREE MED | AL21: 3 | AN21: =AM21*AL21 -> 0 | AS21: =AR21*AQ21 -> 0
B22: 1 | C22: 2 | D22: 3 | E22: 4 | F22: 5 | G22: 6 | H22: 7 | I22: 8 | J22: 9 | K22: 10 | L22: 11 | M22: 12 | AD22: TTAL HB | AE22: HRAS EXTRAS | AI22: TTAL H EXT | AK22: PEPITO FIRTOLAY | AL22: 1 | AN22: =AM22*AL22 -> 0 | AS22: =AR22*AQ22 -> 0
A23: MATRINONIAL | E23: 1 | F23: 1 | G23: 1 | J23: 1 | K23: 1 | L23: 1 | M23: 1 | AD23: =+C34+D34+F34+J34+L34+M34 -> 4 | AI23: =SUM(AE23:AH23) -> 0 | AK23: TOSTON TOM | AL23: 2 | AN23: =AM23*AL23 -> 0 | AS23: =AR23*AQ23 -> 0
A24: MNI SUITE | AD24: =+B34+E34+G34+H34+I34+K34 -> 3 | AI24: =SUM(AE24:AH24) -> 0 | AK24: COCOSSETE | AL24: 2 | AN24: =AM24*AL24 -> 0 | AS24: =AR24*AQ24 -> 0
AI25: =SUM(AE25:AH25) -> 0 | AK25: SAMBA | AL25: 2 | AM25: 1 | AN25: =AM25*AL25 -> 2 | AS25: =AR25*AQ25 -> 0
AI26: =SUM(AE26:AH26) -> 0 | AK26: FREGELL | AL26: 1 | AN26: =AM26*AL26 -> 0 | AS26: =AR26*AQ26 -> 0
AD27: =SUM(AD23:AD26) -> 7 | AN27: =SUM(AN3:AN26) -> 24 | AS27: =SUM(AS3:AS26) -> 3.3
AK29: DAÑOS, SERVICIOS Y EXTRAS
AK30: DESINFECCION | AL30: 5 | AN30: =AM30*AL30 -> 0
AK31: DAÑOS | AL31: 5 | AN31: =AM31*AL31 -> 0
AK32: SERV LAV X PIEZA | AL32: 1 | AN32: =AM32*AL32 -> 0
AK33: DECORACION MOD 1 | AL33: 5 | AN33: =AM33*AL33 -> 0
B34: =SUM(B23:B31) -> 0 | C34: =SUM(C23:C31) -> 0 | D34: =SUM(D23:D31) -> 0 | E34: =SUM(E23:E31) -> 1 | F34: =SUM(F23:F31) -> 1 | G34: =SUM(G23:G31) -> 1 | H34: =SUM(H23:H31) -> 0 | I34: =SUM(I23:I31) -> 0 | ... AC34: =SUM(AC23:AC31) -> 0 | AK34: DECORACION MOD 2 | AL34: 5 | AN34: =AM34*AL34 -> 0
AK35: DECORACION MOD 3 | AL35: 5 | AN35: =AM35*AL35 -> 0
A36: CUADRE DE CAJA | O36: SENCILLA | S36: PERNOCTA | Z36: TOTAL HABITACIÓN | AF36: =O42+S42 -> 39 | AK36: OTROS DAÑOS | AL36: 5 | AN36: =AM36*AL36 -> 0
A37: HABITACIÓN | D37: SENCILLA | F37: HORAS ADICIONAL | H37: PERNOTA | L37: HABITACIÓN | O37: CANTID. HAB | Q37: HORAS ADIC | S37: CANTID. HAB | U37: VENTA | Z37: TOTAL VENTA HOTEL | AF37: =U42 -> 522 | AN37: =SUM(AN30:AN36) -> 0
A38: MATRINONIAL | D38: 10 | F38: 2.5 | H38: 20 | L38: MATRINONIAL | O38: =AD7 -> 15 | Q38: =AI7 -> 4 | S38: =AD23 -> 4 | U38: =S38*H38+O38*D38+Q38*F38 -> 240 | Z38: ACOMPAÑATE | AF38: =AN39 -> 0
A39: MINI SUITE | D39: 12 | F39: 3 | H39: 24 | L39: DOBLE | O39: =AD8 -> 17 | Q39: =AI8 -> 2 | S39: =AD24 -> 3 | U39: =S39*H39+O39*D39+Q39*F39 -> 282 | Z39: DAÑOS, SERV Y OTROS | AF39: =AN37 -> 0 | AK39: ACOMPAÑANTE | AL39: 5 | AN39: =AM39*AL39 -> 0
L40: MINI SUIT | O40: =AD9 -> 0 | Q40: =AI9 -> 0 | S40: =AD25 -> 0 | U40: =S40*H40+O40*D40+Q40*F40 -> 0 | Z40: MINI BAR | AF40: =+AN27+AS27 -> 27.3
L41: SUIT | O41: =AD10 -> 0 | Q41: =AI10 -> 0 | S41: =AD26 -> 0 | U41: =S41*H41+O41*D41+Q41*F41 -> 0 | Z41: TOTAL VENTA HOTEL | AF41: =SUM(AF37:AF40) -> 549.3
...

Sheet CIERRE DOMINGO
A1: *
C4: TASA INTERNA
D5: {=+'DOMINGO 12'!P2:Q2} -> 890 | E5: 0
B6: 45758
B7: ='DOMINGO 12'!F1 -> 46243
B8: TOTAL HABITACIONES | C8: ='DOMINGO 12'!AF36 -> 39
B9: VENTAS HABITACIONES | C9: ='DOMINGO 12'!AF37*'DOMINGO 12'!P2 -> 464580 | D9: =+C9/D5 -> 522
B10: INGRESO DE ACOMPAÑANTE | C10: =+'DOMINGO 12'!AF38*'CIERRE DOMINGO'!D5 -> 0 | D10: =C10/D5 -> 0
B11: VENTAS MINI BAR | C11: ='DOMINGO 12'!AF40*'DOMINGO 12'!P2 -> 24297 | D11: =+C11/D5 -> 27.3
B12: DAÑOS, SERV Y OTROS | C12: =+'DOMINGO 12'!AF39*'CIERRE DOMINGO'!D5 -> 0 | D12: =C12/D5 -> 0
D13: =+C13/D5 -> 0
B15: TOTAL VENTAS | C15: =SUM(C9:C14) -> 488877 | D15: =+C15/D5 -> 549.3
B17: DISPONIBLE
B18: DESCRIPCION | C18: DESGLOSE | D18: INGRESO REAL DIARIO
B19: DIVISAS | C19: ='DOMINGO 12'!S47 -> 251 | D19: =+C19 -> 251
B20: EFECTIVO BSS | C20: ='DOMINGO 12'!S45 -> 1780 | D20: =+C20/D5 -> 2
B21: TRANSF / PAGO MOVIL | C21: ='DOMINGO 12'!S46 -> 258367 | D21: =+C21/D5 -> 290.3
B22: ZELLE
B23: EFECTIVO $ | C23: =+C19 -> 251 | D23: =SUM(D19:D22) -> 543.3
B24: EFECTIVO BS | C24: =+C20 -> 1780 | D24: =D23-D15 -> -6
B26: EGRESOS | C26: BS | D26: $
C32: =SUM(C27:C31) -> 0 | D32: =SUM(D27:D31) -> 0
B34: EFECTIVO VENTA DIARIA BS | C34: =+C24 -> 1780
B35: EFECTIVO VENTA DIARIA $ | C35: =+C23 -> 251
B36: EGRESOS BS | C36: =+C32 -> 0
B37: EGRESOS $ | C37: =+D32 -> 0
B38: TOTAL A ENTREGAR $ | C38: =+C35-C37 -> 251
B39: TOTAL ENTREGAR BS EFEC | C39: =+C34-C36 -> 1780
B41: OBSERVACION:

Sheet VENTA NETA
B2: HOTEL | G2: TASA PROMEDIO | H2: 64
B4: DIAS SEMANA | C4: HABITACION | D4: VENTA | E4: DIVISAS | F4: EFECTIVO | G4: PUNTO VENTA | H4: PAGO MOVIL
B5: LUNES | C5: =LUNES!I98 -> 25 | D5: =LUNES!I99 -> #REF! | E5: =LUNES!AC96+LUNES!AH96 -> 55 | F5: =LUNES!AC91+LUNES!AH91 -> 0 | G5: =LUNES!AC93+LUNES!AH93 -> 0 | H5: =LUNES!AC92+LUNES!AH92 -> 112000
B6: MARTES | C6: =LUNES!R36 -> 0 | D6: =LUNES!R37 -> 0 | E6: =MARTES!AA41+MARTES!AF41 -> 341.5 | F6: =MARTES!AA36+MARTES!AF36 -> 25 | G6: =MARTES!AA38+MARTES!AF38 -> 0 | H6: =MARTES!AA37+MARTES!AF37 -> 324
B7: MIÉRCOLES | C7: =#REF! -> #REF! | D7: =#REF! -> #REF! | E7: =#REF!+#REF! -> #REF! | F7: =#REF!+#REF! -> #REF! | G7: =#REF!+#REF! -> #REF! | H7: =#REF!+#REF! -> #REF!
B8: JUEVES | C8: =#REF! -> #REF! | D8: =#REF! -> #REF! | E8: =#REF!+#REF! -> #REF! | F8: =#REF!+#REF! -> #REF! | G8: =#REF!+#REF! -> #REF! | H8: =#REF!+#REF! -> #REF!
B9: VIERNES | C9: =#REF! -> #REF! | D9: =#REF! -> #REF! | E9: =#REF!+#REF! -> #REF! | F9: =#REF!+#REF! -> #REF! | G9: =#REF!+#REF! -> #REF! | H9: =#REF!+#REF! -> #REF! | I9: =SUM(H5:H9)+SUM(G5:G9) -> #REF!
B10: SÁBADO | C10: =#REF! -> #REF! | D10: =#REF! -> #REF! | E10: =#REF!+#REF! -> #REF! | F10: =#REF!+#REF! -> #REF! | G10: =#REF!+#REF! -> #REF! | H10: =#REF!+#REF! -> #REF!
B11: DOMINGO | C11: ='DOMINGO 12'!G43 -> 0 | D11: ='DOMINGO 12'!G44 -> 0 | E11: ='DOMINGO 12'!AA41+'DOMINGO 12'!AF41 -> 549.3 | F11: ='DOMINGO 12'!AA36+'DOMINGO 12'!AF36 -> 39 | G11: ='DOMINGO 12'!AA38+'DOMINGO 12'!AF38 -> 0 | H11: ='DOMINGO 12'!AA37+'DOMINGO 12'!AF37 -> 522 | I11: =SUM(G10:G11:H10:H11) -> #REF!
F12: =SUM(F5:F11) -> #REF! | G12: =SUM(G5:G11) -> #REF! | H12: =SUM(H5:H11) -> #REF!
B13: TOTALES | C13: =SUM(C5:C11) -> #REF! | D13: =SUM(D5:D11) -> #REF! | E13: =SUM(E5:E11) -> #REF! | F13: =F12/H2 -> #REF! | G13: =G12/H2 -> #REF! | H13: =H12/H2 -> #REF! | I13: =SUM(E13:H13) -> #REF!
B17: MINI BAR
B19: DIAS | C19: VENTA
B20: LUNES | C20: =LUNES!I100 -> 3.5
B21: MARTES | C21: =LUNES!R38 -> 0
B22: MIÉRCOLES | C22: =#REF! -> #REF!
B23: JUEVES | C23: =#REF! -> #REF!
B24: VIERNES | C24: =#REF! -> #REF! | H24: =SUM(G20:G24) -> 0 | I24: CORTE VIERNES
B25: SÁBADO | C25: =#REF! -> #REF!
B26: DOMINGO | C26: ='DOMINGO 12'!G45 -> 0 | H26: =SUM(G25+G26) -> 0 | I26: CORTE DOMINGO
B28: TOTAL | C28: =SUM(C20:C27) -> #REF!
C30: =D13+C28-I13 -> #REF!
B33: SOBRANTES Y FALTANTES
B34: DIAS SEMANA | C34: DIFERENCIA | D34: RESPONSABLE
B35: LUNES | C35: =LUNES!I103 -> #REF! | D35: =LUNES!F2 -> SARA
B36: MARTES | C36: =LUNES!R41 -> 0 | D36: =MARTES!Q2 -> 0
B37: MIÉRCOLES | C37: =#REF! -> #REF! | D37: =#REF! -> #REF!
B38: JUEVES | C38: =#REF! -> #REF! | D38: =#REF! -> #REF!
B39: VIERNES | C39: =#REF! -> #REF! | D39: =#REF! -> #REF!
B40: SÁBADO | C40: =#REF! -> #REF! | D40: =#REF! -> #REF!
B41: DOMINGO | C41: ='DOMINGO 12'!G48 -> 0 | D41: ='DOMINGO 12'!Q2 -> 0
B42: TOTALES | C42: =SUM(C35:C41) -> #REF!

Sheet CIERRE VIE A DOM
G5: TASA VIERNES | H5: TASA SABADO | I5: TASA DOMINGO
B6: 45758
G7: ='CIERRE VIERNES'!D5 -> 890 | H7: ='CIERRE SABADO'!D5 -> 890 | I7: ='CIERRE DOMINGO'!D5 -> 890 | J7: 650
B8: TOTAL HABITACIONES | C8: =+'CIERRE VIERNES'!C8+'CIERRE SABADO'!C8+'CIERRE DOMINGO'!C8 -> 115
B9: VENTAS HABITACIONES VIERNES | C9: =+'CIERRE VIERNES'!C9 -> 352885 | D9: =+C9/G7 -> 396.5
B10: VENTAS HABITACIONES SABADO | C10: =+'CIERRE SABADO'!C9 -> 505520 | D10: =+C10/H7 -> 568
B11: VENTAS HABITACIONES DOMIGO | C11: =+'CIERRE DOMINGO'!C9 -> 464580 | D11: =+C11/I7 -> 522
B13: INGRESO DE ACOMPAÑANTE VIERNES | C13: =+'CIERRE VIERNES'!C10 -> 0 | D13: =+C13/G7 -> 0
B14: INGRESO DE ACOMPAÑANTE SABADO | C14: =+'CIERRE SABADO'!C10 -> 0 | D14: =+C14/H7 -> 0
B15: INGRESO DE ACOMPAÑANTE DOMINGO | C15: =+'CIERRE DOMINGO'!C10 -> 0 | D15: =+C15/I7 -> 0
B17: VENTAS MINI BAR VIERNES | C17: =+'CIERRE VIERNES'!C11 -> 20737 | D17: =+C17/G7 -> 23.3
B18: VENTAS MINI BAR SABADO | C18: =+'CIERRE SABADO'!C11 -> 61855 | D18: =+C18/H7 -> 69.5
B19: VENTAS MINI BAR DOMINGO | C19: =+'CIERRE DOMINGO'!C11 -> 24297 | D19: =+C19/I7 -> 27.3 | G19: EFECTIVO | K19: DIVISA
G20: 10 | I20: =H20*G20 -> 0 | K20: 1 | M20: =L20*K20 -> 0
B21: DAÑOS, SERV Y OTROS VIERNES | C21: =+'CIERRE VIERNES'!C12 -> 0 | D21: =+C21/G7 -> 0 | G21: 20 | I21: =H21*G21 -> 0 | K21: 5 | M21: =L21*K21 -> 0
B22: DAÑOS, SERV Y OTROS SABADO | C22: =+'CIERRE SABADO'!C12 -> 0 | D22: =+C22/H7 -> 0 | G22: 50 | I22: =H22*G22 -> 0 | K22: 10 | M22: =L22*K22 -> 0
B23: DAÑOS, SERV Y OTROS DOMINGO | C23: =+'CIERRE DOMINGO'!C12 -> 0 | D23: =+C23/I7 -> 0 | G23: 100 | I23: =H23*G23 -> 0 | K23: 20 | M23: =L23*K23 -> 0
G24: 200 | I24: =H24*G24 -> 0 | K24: 50 | M24: =L24*K24 -> 0
G25: 500 | I25: =H25*G25 -> 0 | K25: 100 | M25: =L25*K25 -> 0
B26: TOTAL VENTAS | C26: =SUM(C9:C25) -> 1429874 | D26: =+D9+D10+D11+D12+D13+D14+D15+D16+D17+D18+D19+D20+D21+D22+D23+D24 -> 1606.6 | I26: =SUM(I20:I25) -> 0 | M26: =SUM(M19:M25) -> 0
B28: DESCRIPCION | C28: DESGLOSE | D28: INGRESO REAL DIARIO
B29: DIVISAS | C29: =+'CIERRE VIERNES'!C19+'CIERRE SABADO'!C19+'CIERRE DOMINGO'!C19 -> 641 | D29: =+C29 -> 641
B30: EFECTIVO BSS VIERNES | C30: =+'CIERRE VIERNES'!C20 -> 11680 | D30: =+C30/G7 -> 13.123596
B31: EFECTIVO BSS SABADO | C31: =+'CIERRE SABADO'!C20 -> 29370 | D31: =+C31/H7 -> 33
B32: EFECTIVO BSS DOMINGO | C32: =+'CIERRE DOMINGO'!C20 -> 1780 | D32: =+C32/I7 -> 2
B34: PUNTO VENTA
B35: TRANSF / PAGO MOVIL VIERNES | C35: =+'CIERRE VIERNES'!C21 -> 222322 | D35: =+C35/G7 -> 249.8
B36: TRANSF / PAGO MOVIL SABADO | C36: =+'CIERRE SABADO'!C21 -> 322625 | D36: =+C36/H7 -> 362.5
B37: TRANSF / PAGO MOVIL DOMINGO | C37: =+'CIERRE DOMINGO'!C21 -> 258367 | D37: =+C37/I7 -> 290.3
B39: ZELLE
B40: CAMBIO BS X $
B41: CAMBIO $ X BSS
B42: EFECTIVO $ | C42: =+C29+D40 -> 641 | D42: =SUM(D29:D41) -> 1591.7236
B43: EFECTIVO BS | C43: =C30+C31+C33-C41 -> 41050 | D43: =+D42-D26 -> -14.876404
B44: TOTAL PAGO MOVIL Y PDV | C44: =+C35+C36+C37 -> 803314
B45: EGRESOS | C45: BS | D45: $
C50: =SUM(C46:C49) -> 0 | D50: =SUM(D46:D49) -> 0
B52: EFECTIVO VENTA DIARIA BS | C52: =+C43 -> 41050
B53: EFECTIVO VENTA DIARIA $ | C53: =+C42 -> 641
B54: EGRESOS BS | C54: =+C50 -> 0
...

Sheet INFO VENTAS MINI BAR
A3: VENTAS MINI BAR X SEMANA
